Workbook

Sheet Model SSD_1
A1: Model SSD_1 w/o limits | F1: Incoming goods Retail, Unit/ Week | G1: Warehouse Retail, Unit | H1: Outgoing goods Retail, Unit/ Week | I1: Orders Retail, Unit/ Week | J1: Placed orders Retail, Unit | K1: Outgoing orders Retail, Unit/ Week | L1: Incoming goods Wholesale, Unit/ Week | M1: Warehouse Wholesale, Unit | N1: Outgoing goods Wholesale, Unit/ Week | O1: Orders Wholesale, Unit/ Week | P1: Placed orders Wholesale, Unit | Q1: Outgoing orders Wholesale, Unit/ Week | R1: Incoming goods RWH, Unit/ Week | S1: Warehouse RWH, Unit | T1: Outgoing goods RWH, Unit/ Week | U1: Orders RWH, Unit/ Week | V1: Placed orders RWH, Unit | W1: Outgoing orders RWH, Unit/ Week | X1: Production Factory, Unit/ Week | Y1: Warehouse Factory, Unit | Z1: Outgoing goods Factory, Unit/ Week
A2: TIME STEP | B2: 1 | C2: Week | E2: 0 | F2: 0 | G2: =B4 -> 900 | H2: 0 | I2: 0 | J2: 0 | K2: =IF(J2>=$B$14,$B$14,0) -> 0 | L2: 0 | M2: =B10 -> 1200 | N2: 0 | O2: 0 | P2: 0 | Q2: =IF(P2>=$B$19,$B$19,0) -> 0 | R2: 0 | S2: =B15 -> 1800 | T2: =O2 -> 0 | U2: 0 | V2: 0 | W2: =IF(V2>=$B$24,$B$24,0) -> 0 | X2: 0 | Y2: =$B$20 -> 2400 | Z2: 0 | AA2: 0
E3: 1 | F3: 0 | G3: =MAX(0,G2+(F2-H2)*$B$2) -> 900 | H3: =MAX(0,IF(G3<$B$6,G3,IF(AND(G3>=$B$6+200,MOD(E3,4)=0),200+$B$6,$B$6))) -> 300 | I3: =MAX(0,($B$8-G3)+H3) -> 700 | J3: =MAX(0,I2-K2+J2) -> 0 | K3: =J3 -> 0 | L3: 0 | M3: =MAX(0,M2+(L2-N2)*$B$2) -> 1200 | N3: =IF(M3<OFFSET(K3,-$B$7,0),M3,OFFSET(K3,-$B$7,0)) -> 0 | O3: =MAX(0,$B$13-M3+N3) -> 300 | P3: =O2-Q2+P2 -> 0 | Q3: =P3 -> 0 | R3: 0 | S3: =MAX(0,S2+(R2-T2)*$B$2) -> 1800 | T3: 0 | U3: =MAX(0,($B$18-S3)+T3) -> 300 | V3: =U2+V2-W2 -> 0 | W3: =V3 -> 0 | X3: =$B$21+IF(Y3>=$B$22,-$B$21,IF(Y3>=W3*2,-$B$21*0.5,IF(W3>=Y3*2,$B$21*0.5,0))) -> 400 | Y3: =MAX(0,Y2+X2-Z2) -> 2400 | Z3: 0 | AA3: 1
A4: Initial supply Retail | B4: 900 | C4: Unit | E4: 2 | F4: =OFFSET(N4,-$B$5,0) -> 0 | G4: =MAX(0,G3+(F3-H3)*$B$2) -> 600 | H4: =MAX(0,IF(G4<$B$6,G4,IF(AND(G4>=$B$6+200,MOD(E4,4)=0),200+$B$6,$B$6))) -> 300 | I4: =MAX(0,($B$8-G4)+H4) -> 1000 | J4: =MAX(0,I3-K3+J3) -> 700 | K4: =J4 -> 700 | L4: 0 | M4: =MAX(0,M3+(L3-N3)*$B$2) -> 1200 | N4: =IF(M4<OFFSET(K4,-$B$7,0),M4,OFFSET(K4,-$B$7,0)) -> 0 | O4: =MAX(0,$B$13-M4+N4) -> 300 | P4: =O3-Q3+P3 -> 300 | Q4: =P4 -> 300 | R4: 0 | S4: =MAX(0,S3+(R3-T3)*$B$2) -> 1800 | T4: =IF(S4<OFFSET(Q4,-$B$12,0),S4,OFFSET(Q4,-$B$12,0)) -> 0 | U4: =MAX(0,($B$18-S4)+T4) -> 300 | V4: =U3+V3-W3 -> 300 | W4: =V4 -> 300 | X4: =$B$21+IF(Y4>=$B$22,-$B$21,IF(Y4>=W4*2,-$B$21*0.5,IF(W4>=Y4*2,$B$21*0.5,0))) -> 400 | Y4: =MAX(0,Y3+X3-Z3) -> 2800 | Z4: 0 | AA4: 2
A5: Delivery time to Retail | B5: 2 | C5: Week | E5: 3 | F5: =OFFSET(N5,-$B$5,0) -> 0 | G5: =MAX(0,G4+(F4-H4)*$B$2) -> 300 | H5: =MAX(0,IF(G5<$B$6,G5,IF(AND(G5>=$B$6+200,MOD(E5,4)=0),200+$B$6,$B$6))) -> 300 | I5: =MAX(0,($B$8-G5)+H5) -> 1300 | J5: =MAX(0,I4-K4+J4) -> 1000 | K5: =J5 -> 1000 | L5: =OFFSET(T5,-$B$11,0) -> 0 | M5: =MAX(0,M4+(L4-N4)*$B$2) -> 1200 | N5: =IF(M5<OFFSET(K5,-$B$7,0),M5,OFFSET(K5,-$B$7,0)) -> 700 | O5: =MAX(0,$B$13-M5+N5) -> 1000 | P5: =O4-Q4+P4 -> 300 | Q5: =P5 -> 300 | R5: 0 | S5: =MAX(0,S4+(R4-T4)*$B$2) -> 1800 | T5: =IF(S5<OFFSET(Q5,-$B$12,0),S5,OFFSET(Q5,-$B$12,0)) -> 0 | U5: =MAX(0,($B$18-S5)+T5) -> 300 | V5: =U4+V4-W4 -> 300 | W5: =V5 -> 300 | X5: =$B$21+IF(Y5>=$B$22,-$B$21,IF(Y5>=W5*2,-$B$21*0.5,IF(W5>=Y5*2,$B$21*0.5,0))) -> 400 | Y5: =MAX(0,Y4+X4-Z4) -> 3200 | Z5: =IF(Y5<OFFSET(W5,-$B$17,0),Y5,OFFSET(W5,-$B$17,0)) -> 0 | AA5: 3
A6: Average amount of sales Retail | B6: 300 | C6: Unit/ Week | E6: 4 | F6: =OFFSET(N6,-$B$5,0) -> 0 | G6: =MAX(0,G5+(F5-H5)*$B$2) -> 0 | H6: =MAX(0,IF(G6<$B$6,G6,IF(AND(G6>=$B$6+200,MOD(E6,4)=0),200+$B$6,$B$6))) -> 0 | I6: =MAX(0,($B$8-G6)+H6) -> 1300 | J6: =MAX(0,I5-K5+J5) -> 1300 | K6: =J6 -> 1300 | L6: 0 | M6: =MAX(0,M5+(L5-N5)*$B$2) -> 500 | N6: =IF(M6<OFFSET(K6,-$B$7,0),M6,OFFSET(K6,-$B$7,0)) -> 500 | O6: =MAX(0,$B$13-M6+N6) -> 1500 | P6: =O5-Q5+P5 -> 1000 | Q6: =P6 -> 1000 | R6: =OFFSET(Z6,-$B$16,0) -> 0 | S6: =MAX(0,S5+(R5-T5)*$B$2) -> 1800 | T6: =IF(S6<OFFSET(Q6,-$B$12,0),S6,OFFSET(Q6,-$B$12,0)) -> 300 | U6: =MAX(0,($B$18-S6)+T6) -> 600 | V6: =U5+V5-W5 -> 300 | W6: =V6 -> 300 | X6: =$B$21+IF(Y6>=$B$22,-$B$21,IF(Y6>=W6*2,-$B$21*0.5,IF(W6>=Y6*2,$B$21*0.5,0))) -> 400 | Y6: =MAX(0,Y5+X5-Z5) -> 3600 | Z6: =IF(Y6<OFFSET(W6,-$B$17,0),Y6,OFFSET(W6,-$B$17,0)) -> 0 | AA6: 4
A7: Time to fill oder for Retail | B7: 1 | C7: Week | E7: 5 | F7: =OFFSET(N7,-$B$5,0) -> 700 | G7: =MAX(0,G6+(F6-H6)*$B$2) -> 0 | H7: =MAX(0,IF(G7<$B$6,G7,IF(AND(G7>=$B$6+200,MOD(E7,4)=0),200+$B$6,$B$6))) -> 0 | I7: =MAX(0,($B$8-G7)+H7) -> 1300 | J7: =MAX(0,I6-K6+J6) -> 1300 | K7: =J7 -> 1300 | L7: =OFFSET(T7,-$B$11,0) -> 0 | M7: =MAX(0,M6+(L6-N6)*$B$2) -> 0 | N7: =IF(M7<OFFSET(K7,-$B$7,0),M7,OFFSET(K7,-$B$7,0)) -> 0 | O7: =MAX(0,$B$13-M7+N7) -> 1500 | P7: =O6-Q6+P6 -> 1500 | Q7: =P7 -> 1500 | R7: =OFFSET(Z7,-$B$16,0) -> 0 | S7: =MAX(0,S6+(R6-T6)*$B$2) -> 1500 | T7: =IF(S7<OFFSET(Q7,-$B$12,0),S7,OFFSET(Q7,-$B$12,0)) -> 300 | U7: =MAX(0,($B$18-S7)+T7) -> 900 | V7: =U6+V6-W6 -> 600 | W7: =V7 -> 600 | X7: =$B$21+IF(Y7>=$B$22,-$B$21,IF(Y7>=W7*2,-$B$21*0.5,IF(W7>=Y7*2,$B$21*0.5,0))) -> 400 | Y7: =MAX(0,Y6+X6-Z6) -> 4000 | Z7: =IF(Y7<OFFSET(W7,-$B$17,0),Y7,OFFSET(W7,-$B$17,0)) -> 300 | AA7: 5
A8: Desired supply Retail | B8: 1300 | C8: Unit | E8: 6 | F8: =OFFSET(N8,-$B$5,0) -> 500 | G8: =MAX(0,G7+(F7-H7)*$B$2) -> 700 | H8: =MAX(0,IF(G8<$B$6,G8,IF(AND(G8>=$B$6+200,MOD(E8,4)=0),200+$B$6,$B$6))) -> 300 | I8: =MAX(0,($B$8-G8)+H8) -> 900 | J8: =MAX(0,I7-K7+J7) -> 1300 | K8: =J8 -> 1300 | L8: =OFFSET(T8,-$B$11,0) -> 0 | M8: =MAX(0,M7+(L7-N7)*$B$2) -> 0 | N8: =IF(M8<OFFSET(K8,-$B$7,0),M8,OFFSET(K8,-$B$7,0)) -> 0 | O8: =MAX(0,$B$13-M8+N8) -> 1500 | P8: =O7-Q7+P7 -> 1500 | Q8: =P8 -> 1500 | R8: =OFFSET(Z8,-$B$16,0) -> 0 | S8: =MAX(0,S7+(R7-T7)*$B$2) -> 1200 | T8: =IF(S8<OFFSET(Q8,-$B$12,0),S8,OFFSET(Q8,-$B$12,0)) -> 1000 | U8: =MAX(0,($B$18-S8)+T8) -> 1900 | V8: =U7+V7-W7 -> 900 | W8: =V8 -> 900 | X8: =$B$21+IF(Y8>=$B$22,-$B$21,IF(Y8>=W8*2,-$B$21*0.5,IF(W8>=Y8*2,$B$21*0.5,0))) -> 400 | Y8: =MAX(0,Y7+X7-Z7) -> 4100 | Z8: =IF(Y8<OFFSET(W8,-$B$17,0),Y8,OFFSET(W8,-$B$17,0)) -> 300 | AA8: 6
E9: 7 | F9: =OFFSET(N9,-$B$5,0) -> 0 | G9: =MAX(0,G8+(F8-H8)*$B$2) -> 900 | H9: =MAX(0,IF(G9<$B$6,G9,IF(AND(G9>=$B$6+200,MOD(E9,4)=0),200+$B$6,$B$6))) -> 300 | I9: =MAX(0,($B$8-G9)+H9) -> 700 | J9: =MAX(0,I8-K8+J8) -> 900 | K9: =J9 -> 900 | L9: =OFFSET(T9,-$B$11,0) -> 300 | M9: =MAX(0,M8+(L8-N8)*$B$2) -> 0 | N9: =IF(M9<OFFSET(K9,-$B$7,0),M9,OFFSET(K9,-$B$7,0)) -> 0 | O9: =MAX(0,$B$13-M9+N9) -> 1500 | P9: =O8-Q8+P8 -> 1500 | Q9: =P9 -> 1500 | R9: =OFFSET(Z9,-$B$16,0) -> 0 | S9: =MAX(0,S8+(R8-T8)*$B$2) -> 200 | T9: =IF(S9<OFFSET(Q9,-$B$12,0),S9,OFFSET(Q9,-$B$12,0)) -> 200 | U9: =MAX(0,($B$18-S9)+T9) -> 2100 | V9: =U8+V8-W8 -> 1900 | W9: =V9 -> 1900 | X9: =$B$21+IF(Y9>=$B$22,-$B$21,IF(Y9>=W9*2,-$B$21*0.5,IF(W9>=Y9*2,$B$21*0.5,0))) -> 400 | Y9: =MAX(0,Y8+X8-Z8) -> 4200 | Z9: =IF(Y9<OFFSET(W9,-$B$17,0),Y9,OFFSET(W9,-$B$17,0)) -> 300 | AA9: 7
A10: Initial supply Wholesale | B10: 1200 | C10: Unit | E10: 8 | F10: =OFFSET(N10,-$B$5,0) -> 0 | G10: =MAX(0,G9+(F9-H9)*$B$2) -> 600 | H10: =MAX(0,IF(G10<$B$6,G10,IF(AND(G10>=$B$6+200,MOD(E10,4)=0),200+$B$6,$B$6))) -> 500 | I10: =MAX(0,($B$8-G10)+H10) -> 1200 | J10: =MAX(0,I9-K9+J9) -> 700 | K10: =J10 -> 700 | L10: =OFFSET(T10,-$B$11,0) -> 300 | M10: =MAX(0,M9+(L9-N9)*$B$2) -> 300 | N10: =IF(M10<OFFSET(K10,-$B$7,0),M10,OFFSET(K10,-$B$7,0)) -> 300 | O10: =MAX(0,$B$13-M10+N10) -> 1500 | P10: =O9-Q9+P9 -> 1500 | Q10: =P10 -> 1500 | R10: =OFFSET(Z10,-$B$16,0) -> 0 | S10: =MAX(0,S9+(R9-T9)*$B$2) -> 0 | T10: =IF(S10<OFFSET(Q10,-$B$12,0),S10,OFFSET(Q10,-$B$12,0)) -> 0 | U10: =MAX(0,($B$18-S10)+T10) -> 2100 | V10: =U9+V9-W9 -> 2100 | W10: =V10 -> 2100 | X10: =$B$21+IF(Y10>=$B$22,-$B$21,IF(Y10>=W10*2,-$B$21*0.5,IF(W10>=Y10*2,$B$21*0.5,0))) -> 400 | Y10: =MAX(0,Y9+X9-Z9) -> 4300 | Z10: =IF(Y10<OFFSET(W10,-$B$17,0),Y10,OFFSET(W10,-$B$17,0)) -> 600 | AA10: 8
A11: Delivery time to Wholesale | B11: 3 | C11: Week | E11: 9 | F11: =OFFSET(N11,-$B$5,0) -> 0 | G11: =MAX(0,G10+(F10-H10)*$B$2) -> 100 | H11: =MAX(0,IF(G11<$B$6,G11,IF(AND(G11>=$B$6+200,MOD(E11,4)=0),200+$B$6,$B$6))) -> 100 | I11: =MAX(0,($B$8-G11)+H11) -> 1300 | J11: =MAX(0,I10-K10+J10) -> 1200 | K11: =J11 -> 1200 | L11: =OFFSET(T11,-$B$11,0) -> 1000 | M11: =MAX(0,M10+(L10-N10)*$B$2) -> 300 | N11: =IF(M11<OFFSET(K11,-$B$7,0),M11,OFFSET(K11,-$B$7,0)) -> 300 | O11: =MAX(0,$B$13-M11+N11) -> 1500 | P11: =O10-Q10+P10 -> 1500 | Q11: =P11 -> 1500 | R11: =OFFSET(Z11,-$B$16,0) -> 300 | S11: =MAX(0,S10+(R10-T10)*$B$2) -> 0 | T11: =IF(S11<OFFSET(Q11,-$B$12,0),S11,OFFSET(Q11,-$B$12,0)) -> 0 | U11: =MAX(0,($B$18-S11)+T11) -> 2100 | V11: =U10+V10-W10 -> 2100 | W11: =V11 -> 2100 | X11: =$B$21+IF(Y11>=$B$22,-$B$21,IF(Y11>=W11*2,-$B$21*0.5,IF(W11>=Y11*2,$B$21*0.5,0))) -> 800 | Y11: =MAX(0,Y10+X10-Z10) -> 4100 | Z11: =IF(Y11<OFFSET(W11,-$B$17,0),Y11,OFFSET(W11,-$B$17,0)) -> 900 | AA11: 9
A12: Time to fill oder for Wholesale | B12: 2 | C12: Week | E12: 10 | F12: =OFFSET(N12,-$B$5,0) -> 300 | G12: =MAX(0,G11+(F11-H11)*$B$2) -> 0 | H12: =MAX(0,IF(G12<$B$6,G12,IF(AND(G12>=$B$6+200,MOD(E12,4)=0),200+$B$6,$B$6))) -> 0 | I12: =MAX(0,($B$8-G12)+H12) -> 1300 | J12: =MAX(0,I11-K11+J11) -> 1300 | K12: =J12 -> 1300 | L12: =OFFSET(T12,-$B$11,0) -> 200 | M12: =MAX(0,M11+(L11-N11)*$B$2) -> 1000 | N12: =IF(M12<OFFSET(K12,-$B$7,0),M12,OFFSET(K12,-$B$7,0)) -> 1000 | O12: =MAX(0,$B$13-M12+N12) -> 1500 | P12: =O11-Q11+P11 -> 1500 | Q12: =P12 -> 1500 | R12: =OFFSET(Z12,-$B$16,0) -> 300 | S12: =MAX(0,S11+(R11-T11)*$B$2) -> 300 | T12: =IF(S12<OFFSET(Q12,-$B$12,0),S12,OFFSET(Q12,-$B$12,0)) -> 300 | U12: =MAX(0,($B$18-S12)+T12) -> 2100 | V12: =U11+V11-W11 -> 2100 | W12: =V12 -> 2100 | X12: =$B$21+IF(Y12>=$B$22,-$B$21,IF(Y12>=W12*2,-$B$21*0.5,IF(W12>=Y12*2,$B$21*0.5,0))) -> 800 | Y12: =MAX(0,Y11+X11-Z11) -> 4000 | Z12: =IF(Y12<OFFSET(W12,-$B$17,0),Y12,OFFSET(W12,-$B$17,0)) -> 1900 | AA12: 10
A13: Desired supply Wholesale | B13: 1500 | C13: Unit | E13: 11 | F13: =OFFSET(N13,-$B$5,0) -> 300 | G13: =MAX(0,G12+(F12-H12)*$B$2) -> 300 | H13: =MAX(0,IF(G13<$B$6,G13,IF(AND(G13>=$B$6+200,MOD(E13,4)=0),200+$B$6,$B$6))) -> 300 | I13: =MAX(0,($B$8-G13)+H13) -> 1300 | J13: =MAX(0,I12-K12+J12) -> 1300 | K13: =J13 -> 1300 | L13: =OFFSET(T13,-$B$11,0) -> 0 | M13: =MAX(0,M12+(L12-N12)*$B$2) -> 200 | N13: =IF(M13<OFFSET(K13,-$B$7,0),M13,OFFSET(K13,-$B$7,0)) -> 200 | O13: =MAX(0,$B$13-M13+N13) -> 1500 | P13: =O12-Q12+P12 -> 1500 | Q13: =P13 -> 1500 | R13: =OFFSET(Z13,-$B$16,0) -> 300 | S13: =MAX(0,S12+(R12-T12)*$B$2) -> 300 | T13: =IF(S13<OFFSET(Q13,-$B$12,0),S13,OFFSET(Q13,-$B$12,0)) -> 300 | U13: =MAX(0,($B$18-S13)+T13) -> 2100 | V13: =U12+V12-W12 -> 2100 | W13: =V13 -> 2100 | X13: =$B$21+IF(Y13>=$B$22,-$B$21,IF(Y13>=W13*2,-$B$21*0.5,IF(W13>=Y13*2,$B$21*0.5,0))) -> 800 | Y13: =MAX(0,Y12+X12-Z12) -> 2900 | Z13: =IF(Y13<OFFSET(W13,-$B$17,0),Y13,OFFSET(W13,-$B$17,0)) -> 2100 | AA13: 11
E14: 12 | F14: =OFFSET(N14,-$B$5,0) -> 1000 | G14: =MAX(0,G13+(F13-H13)*$B$2) -> 300 | H14: =MAX(0,IF(G14<$B$6,G14,IF(AND(G14>=$B$6+200,MOD(E14,4)=0),200+$B$6,$B$6))) -> 300 | I14: =MAX(0,($B$8-G14)+H14) -> 1300 | J14: =MAX(0,I13-K13+J13) -> 1300 | K14: =J14 -> 1300 | L14: =OFFSET(T14,-$B$11,0) -> 0 | M14: =MAX(0,M13+(L13-N13)*$B$2) -> 0 | N14: =IF(M14<OFFSET(K14,-$B$7,0),M14,OFFSET(K14,-$B$7,0)) -> 0 | O14: =MAX(0,$B$13-M14+N14) -> 1500 | P14: =O13-Q13+P13 -> 1500 | Q14: =P14 -> 1500 | R14: =OFFSET(Z14,-$B$16,0) -> 600 | S14: =MAX(0,S13+(R13-T13)*$B$2) -> 300 | T14: =IF(S14<OFFSET(Q14,-$B$12,0),S14,OFFSET(Q14,-$B$12,0)) -> 300 | U14: =MAX(0,($B$18-S14)+T14) -> 2100 | V14: =U13+V13-W13 -> 2100 | W14: =V14 -> 2100 | X14: =$B$21+IF(Y14>=$B$22,-$B$21,IF(Y14>=W14*2,-$B$21*0.5,IF(W14>=Y14*2,$B$21*0.5,0))) -> 800 | Y14: =MAX(0,Y13+X13-Z13) -> 1600 | Z14: =IF(Y14<OFFSET(W14,-$B$17,0),Y14,OFFSET(W14,-$B$17,0)) -> 1600 | AA14: 12
A15: Initial supply Regional Warehouse | B15: 1800 | C15: Unit | E15: 13 | F15: =OFFSET(N15,-$B$5,0) -> 200 | G15: =MAX(0,G14+(F14-H14)*$B$2) -> 1000 | H15: =MAX(0,IF(G15<$B$6,G15,IF(AND(G15>=$B$6+200,MOD(E15,4)=0),200+$B$6,$B$6))) -> 300 | I15: =MAX(0,($B$8-G15)+H15) -> 600 | J15: =MAX(0,I14-K14+J14) -> 1300 | K15: =J15 -> 1300 | L15: =OFFSET(T15,-$B$11,0) -> 300 | M15: =MAX(0,M14+(L14-N14)*$B$2) -> 0 | N15: =IF(M15<OFFSET(K15,-$B$7,0),M15,OFFSET(K15,-$B$7,0)) -> 0 | O15: =MAX(0,$B$13-M15+N15) -> 1500 | P15: =O14-Q14+P14 -> 1500 | Q15: =P15 -> 1500 | R15: =OFFSET(Z15,-$B$16,0) -> 900 | S15: =MAX(0,S14+(R14-T14)*$B$2) -> 600 | T15: =IF(S15<OFFSET(Q15,-$B$12,0),S15,OFFSET(Q15,-$B$12,0)) -> 600 | U15: =MAX(0,($B$18-S15)+T15) -> 2100 | V15: =U14+V14-W14 -> 2100 | W15: =V15 -> 2100 | X15: =$B$21+IF(Y15>=$B$22,-$B$21,IF(Y15>=W15*2,-$B$21*0.5,IF(W15>=Y15*2,$B$21*0.5,0))) -> 1200 | Y15: =MAX(0,Y14+X14-Z14) -> 800 | Z15: =IF(Y15<OFFSET(W15,-$B$17,0),Y15,OFFSET(W15,-$B$17,0)) -> 800 | AA15: 13
A16: Delivery time to Regional Warehouse | B16: 4 | C16: Week | E16: 14 | F16: =OFFSET(N16,-$B$5,0) -> 0 | G16: =MAX(0,G15+(F15-H15)*$B$2) -> 900 | H16: =MAX(0,IF(G16<$B$6,G16,IF(AND(G16>=$B$6+200,MOD(E16,4)=0),200+$B$6,$B$6))) -> 300 | I16: =MAX(0,($B$8-G16)+H16) -> 700 | J16: =MAX(0,I15-K15+J15) -> 600 | K16: =J16 -> 600 | L16: =OFFSET(T16,-$B$11,0) -> 300 | M16: =MAX(0,M15+(L15-N15)*$B$2) -> 300 | N16: =IF(M16<OFFSET(K16,-$B$7,0),M16,OFFSET(K16,-$B$7,0)) -> 300 | O16: =MAX(0,$B$13-M16+N16) -> 1500 | P16: =O15-Q15+P15 -> 1500 | Q16: =P16 -> 1500 | R16: =OFFSET(Z16,-$B$16,0) -> 1900 | S16: =MAX(0,S15+(R15-T15)*$B$2) -> 900 | T16: =IF(S16<OFFSET(Q16,-$B$12,0),S16,OFFSET(Q16,-$B$12,0)) -> 900 | U16: =MAX(0,($B$18-S16)+T16) -> 2100 | V16: =U15+V15-W15 -> 2100 | W16: =V16 -> 2100 | X16: =$B$21+IF(Y16>=$B$22,-$B$21,IF(Y16>=W16*2,-$B$21*0.5,IF(W16>=Y16*2,$B$21*0.5,0))) -> 800 | Y16: =MAX(0,Y15+X15-Z15) -> 1200 | Z16: =IF(Y16<OFFSET(W16,-$B$17,0),Y16,OFFSET(W16,-$B$17,0)) -> 1200 | AA16: 14
A17: Time to fill oder for to Regional Warehouse | B17: 3 | C17: Week | E17: 15 | F17: =OFFSET(N17,-$B$5,0) -> 0 | G17: =MAX(0,G16+(F16-H16)*$B$2) -> 600 | H17: =MAX(0,IF(G17<$B$6,G17,IF(AND(G17>=$B$6+200,MOD(E17,4)=0),200+$B$6,$B$6))) -> 300 | I17: =MAX(0,($B$8-G17)+H17) -> 1000 | J17: =MAX(0,I16-K16+J16) -> 700 | K17: =J17 -> 700 | L17: =OFFSET(T17,-$B$11,0) -> 300 | M17: =MAX(0,M16+(L16-N16)*$B$2) -> 300 | N17: =IF(M17<OFFSET(K17,-$B$7,0),M17,OFFSET(K17,-$B$7,0)) -> 300 | O17: =MAX(0,$B$13-M17+N17) -> 1500 | P17: =O16-Q16+P16 -> 1500 | Q17: =P17 -> 1500 | R17: =OFFSET(Z17,-$B$16,0) -> 2100 | S17: =MAX(0,S16+(R16-T16)*$B$2) -> 1900 | T17: =IF(S17<OFFSET(Q17,-$B$12,0),S17,OFFSET(Q17,-$B$12,0)) -> 1500 | U17: =MAX(0,($B$18-S17)+T17) -> 1700 | V17: =U16+V16-W16 -> 2100 | W17: =V17 -> 2100 | X17: =$B$21+IF(Y17>=$B$22,-$B$21,IF(Y17>=W17*2,-$B$21*0.5,IF(W17>=Y17*2,$B$21*0.5,0))) -> 1200 | Y17: =MAX(0,Y16+X16-Z16) -> 800 | Z17: =IF(Y17<OFFSET(W17,-$B$17,0),Y17,OFFSET(W17,-$B$17,0)) -> 800 | AA17: 15
A18: Desired supply Regional Warehouse | B18: 2100 | C18: Unit | E18: 16 | F18: =OFFSET(N18,-$B$5,0) -> 300 | G18: =MAX(0,G17+(F17-H17)*$B$2) -> 300 | H18: =MAX(0,IF(G18<$B$6,G18,IF(AND(G18>=$B$6+200,MOD(E18,4)=0),200+$B$6,$B$6))) -> 300 | I18: =MAX(0,($B$8-G18)+H18) -> 1300 | J18: =MAX(0,I17-K17+J17) -> 1000 | K18: =J18 -> 1000 | L18: =OFFSET(T18,-$B$11,0) -> 600 | M18: =MAX(0,M17+(L17-N17)*$B$2) -> 300 | N18: =IF(M18<OFFSET(K18,-$B$7,0),M18,OFFSET(K18,-$B$7,0)) -> 300 | O18: =MAX(0,$B$13-M18+N18) -> 1500 | P18: =O17-Q17+P17 -> 1500 | Q18: =P18 -> 1500 | R18: =OFFSET(Z18,-$B$16,0) -> 1600 | S18: =MAX(0,S17+(R17-T17)*$B$2) -> 2500 | T18: =IF(S18<OFFSET(Q18,-$B$12,0),S18,OFFSET(Q18,-$B$12,0)) -> 1500 | U18: =MAX(0,($B$18-S18)+T18) -> 1100 | V18: =U17+V17-W17 -> 1700 | W18: =V18 -> 1700 | X18: =$B$21+IF(Y18>=$B$22,-$B$21,IF(Y18>=W18*2,-$B$21*0.5,IF(W18>=Y18*2,$B$21*0.5,0))) -> 800 | Y18: =MAX(0,Y17+X17-Z17) -> 1200 | Z18: =IF(Y18<OFFSET(W18,-$B$17,0),Y18,OFFSET(W18,-$B$17,0)) -> 1200 | AA18: 16
E19: 17 | F19: =OFFSET(N19,-$B$5,0) -> 300 | G19: =MAX(0,G18+(F18-H18)*$B$2) -> 300 | H19: =MAX(0,IF(G19<$B$6,G19,IF(AND(G19>=$B$6+200,MOD(E19,4)=0),200+$B$6,$B$6))) -> 300 | I19: =MAX(0,($B$8-G19)+H19) -> 1300 | J19: =MAX(0,I18-K18+J18) -> 1300 | K19: =J19 -> 1300 | L19: =OFFSET(T19,-$B$11,0) -> 900 | M19: =MAX(0,M18+(L18-N18)*$B$2) -> 600 | N19: =IF(M19<OFFSET(K19,-$B$7,0),M19,OFFSET(K19,-$B$7,0)) -> 600 | O19: =MAX(0,$B$13-M19+N19) -> 1500 | P19: =O18-Q18+P18 -> 1500 | Q19: =P19 -> 1500 | R19: =OFFSET(Z19,-$B$16,0) -> 800 | S19: =MAX(0,S18+(R18-T18)*$B$2) -> 2600 | T19: =IF(S19<OFFSET(Q19,-$B$12,0),S19,OFFSET(Q19,-$B$12,0)) -> 1500 | U19: =MAX(0,($B$18-S19)+T19) -> 1000 | V19: =U18+V18-W18 -> 1100 | W19: =V19 -> 1100 | X19: =$B$21+IF(Y19>=$B$22,-$B$21,IF(Y19>=W19*2,-$B$21*0.5,IF(W19>=Y19*2,$B$21*0.5,0))) -> 800 | Y19: =MAX(0,Y18+X18-Z18) -> 800 | Z19: =IF(Y19<OFFSET(W19,-$B$17,0),Y19,OFFSET(W19,-$B$17,0)) -> 800 | AA19: 17
A20: Initial supply Factory | B20: 2400 | C20: Unit | E20: 18 | F20: =OFFSET(N20,-$B$5,0) -> 300 | G20: =MAX(0,G19+(F19-H19)*$B$2) -> 300 | H20: =MAX(0,IF(G20<$B$6,G20,IF(AND(G20>=$B$6+200,MOD(E20,4)=0),200+$B$6,$B$6))) -> 300 | I20: =MAX(0,($B$8-G20)+H20) -> 1300 | J20: =MAX(0,I19-K19+J19) -> 1300 | K20: =J20 -> 1300 | L20: =OFFSET(T20,-$B$11,0) -> 1500 | M20: =MAX(0,M19+(L19-N19)*$B$2) -> 900 | N20: =IF(M20<OFFSET(K20,-$B$7,0),M20,OFFSET(K20,-$B$7,0)) -> 900 | O20: =MAX(0,$B$13-M20+N20) -> 1500 | P20: =O19-Q19+P19 -> 1500 | Q20: =P20 -> 1500 | R20: =OFFSET(Z20,-$B$16,0) -> 1200 | S20: =MAX(0,S19+(R19-T19)*$B$2) -> 1900 | T20: =IF(S20<OFFSET(Q20,-$B$12,0),S20,OFFSET(Q20,-$B$12,0)) -> 1500 | U20: =MAX(0,($B$18-S20)+T20) -> 1700 | V20: =U19+V19-W19 -> 1000 | W20: =V20 -> 1000 | X20: =$B$21+IF(Y20>=$B$22,-$B$21,IF(Y20>=W20*2,-$B$21*0.5,IF(W20>=Y20*2,$B$21*0.5,0))) -> 800 | Y20: =MAX(0,Y19+X19-Z19) -> 800 | Z20: =IF(Y20<OFFSET(W20,-$B$17,0),Y20,OFFSET(W20,-$B$17,0)) -> 800 | AA20: 18
A21: Average production Factory | B21: 800 | C21: Unit/ Week | E21: 19 | F21: =OFFSET(N21,-$B$5,0) -> 600 | G21: =MAX(0,G20+(F20-H20)*$B$2) -> 300 | H21: =MAX(0,IF(G21<$B$6,G21,IF(AND(G21>=$B$6+200,MOD(E21,4)=0),200+$B$6,$B$6))) -> 300 | I21: =MAX(0,($B$8-G21)+H21) -> 1300 | J21: =MAX(0,I20-K20+J20) -> 1300 | K21: =J21 -> 1300 | L21: =OFFSET(T21,-$B$11,0) -> 1500 | M21: =MAX(0,M20+(L20-N20)*$B$2) -> 1500 | N21: =IF(M21<OFFSET(K21,-$B$7,0),M21,OFFSET(K21,-$B$7,0)) -> 1300 | O21: =MAX(0,$B$13-M21+N21) -> 1300 | P21: =O20-Q20+P20 -> 1500 | Q21: =P21 -> 1500 | R21: =OFFSET(Z21,-$B$16,0) -> 800 | S21: =MAX(0,S20+(R20-T20)*$B$2) -> 1600 | T21: =IF(S21<OFFSET(Q21,-$B$12,0),S21,OFFSET(Q21,-$B$12,0)) -> 1500 | U21: =MAX(0,($B$18-S21)+T21) -> 2000 | V21: =U20+V20-W20 -> 1700 | W21: =V21 -> 1700 | X21: =$B$21+IF(Y21>=$B$22,-$B$21,IF(Y21>=W21*2,-$B$21*0.5,IF(W21>=Y21*2,$B$21*0.5,0))) -> 1200 | Y21: =MAX(0,Y20+X20-Z20) -> 800 | Z21: =IF(Y21<OFFSET(W21,-$B$17,0),Y21,OFFSET(W21,-$B$17,0)) -> 800 | AA21: 19
A22: Max supply Factory | B22: 10000 | C22: Unit | E22: 20 | F22: =OFFSET(N22,-$B$5,0) -> 900 | G22: =MAX(0,G21+(F21-H21)*$B$2) -> 600 | H22: =MAX(0,IF(G22<$B$6,G22,IF(AND(G22>=$B$6+200,MOD(E22,4)=0),200+$B$6,$B$6))) -> 500 | I22: =MAX(0,($B$8-G22)+H22) -> 1200 | J22: =MAX(0,I21-K21+J21) -> 1300 | K22: =J22 -> 1300 | L22: =OFFSET(T22,-$B$11,0) -> 1500 | M22: =MAX(0,M21+(L21-N21)*$B$2) -> 1700 | N22: =IF(M22<OFFSET(K22,-$B$7,0),M22,OFFSET(K22,-$B$7,0)) -> 1300 | O22: =MAX(0,$B$13-M22+N22) -> 1100 | P22: =O21-Q21+P21 -> 1300 | Q22: =P22 -> 1300 | R22: =OFFSET(Z22,-$B$16,0) -> 1200 | S22: =MAX(0,S21+(R21-T21)*$B$2) -> 900 | T22: =IF(S22<OFFSET(Q22,-$B$12,0),S22,OFFSET(Q22,-$B$12,0)) -> 900 | U22: =MAX(0,($B$18-S22)+T22) -> 2100 | V22: =U21+V21-W21 -> 2000 | W22: =V22 -> 2000 | X22: =$B$21+IF(Y22>=$B$22,-$B$21,IF(Y22>=W22*2,-$B$21*0.5,IF(W22>=Y22*2,$B$21*0.5,0))) -> 800 | Y22: =MAX(0,Y21+X21-Z21) -> 1200 | Z22: =IF(Y22<OFFSET(W22,-$B$17,0),Y22,OFFSET(W22,-$B$17,0)) -> 1100 | AA22: 20
E23: 21 | F23: =OFFSET(N23,-$B$5,0) -> 1300 | G23: =MAX(0,G22+(F22-H22)*$B$2) -> 1000 | H23: =MAX(0,IF(G23<$B$6,G23,IF(AND(G23>=$B$6+200,MOD(E23,4)=0),200+$B$6,$B$6))) -> 300 | I23: =MAX(0,($B$8-G23)+H23) -> 600 | J23: =MAX(0,I22-K22+J22) -> 1200 | K23: =J23 -> 1200 | L23: =OFFSET(T23,-$B$11,0) -> 1500 | M23: =MAX(0,M22+(L22-N22)*$B$2) -> 1900 | N23: =IF(M23<OFFSET(K23,-$B$7,0),M23,OFFSET(K23,-$B$7,0)) -> 1300 | O23: =MAX(0,$B$13-M23+N23) -> 900 | P23: =O22-Q22+P22 -> 1100 | Q23: =P23 -> 1100 | R23: =OFFSET(Z23,-$B$16,0) -> 800 | S23: =MAX(0,S22+(R22-T22)*$B$2) -> 1200 | T23: =IF(S23<OFFSET(Q23,-$B$12,0),S23,OFFSET(Q23,-$B$12,0)) -> 1200 | U23: =MAX(0,($B$18-S23)+T23) -> 2100 | V23: =U22+V22-W22 -> 2100 | W23: =V23 -> 2100 | X23: =$B$21+IF(Y23>=$B$22,-$B$21,IF(Y23>=W23*2,-$B$21*0.5,IF(W23>=Y23*2,$B$21*0.5,0))) -> 1200 | Y23: =MAX(0,Y22+X22-Z22) -> 900 | Z23: =IF(Y23<OFFSET(W23,-$B$17,0),Y23,OFFSET(W23,-$B$17,0)) -> 900 | AA23: 21
E24: 22 | F24: =OFFSET(N24,-$B$5,0) -> 1300 | G24: =MAX(0,G23+(F23-H23)*$B$2) -> 2000 | H24: =MAX(0,IF(G24<$B$6,G24,IF(AND(G24>=$B$6+200,MOD(E24,4)=0),200+$B$6,$B$6))) -> 300 | I24: =MAX(0,($B$8-G24)+H24) -> 0 | J24: =MAX(0,I23-K23+J23) -> 600 | K24: =J24 -> 600 | L24: =OFFSET(T24,-$B$11,0) -> 1500 | M24: =MAX(0,M23+(L23-N23)*$B$2) -> 2100 | N24: =IF(M24<OFFSET(K24,-$B$7,0),M24,OFFSET(K24,-$B$7,0)) -> 1200 | O24: =MAX(0,$B$13-M24+N24) -> 600 | P24: =O23-Q23+P23 -> 900 | Q24: =P24 -> 900 | R24: =OFFSET(Z24,-$B$16,0) -> 800 | S24: =MAX(0,S23+(R23-T23)*$B$2) -> 800 | T24: =IF(S24<OFFSET(Q24,-$B$12,0),S24,OFFSET(Q24,-$B$12,0)) -> 800 | U24: =MAX(0,($B$18-S24)+T24) -> 2100 | V24: =U23+V23-W23 -> 2100 | W24: =V24 -> 2100 | X24: =$B$21+IF(Y24>=$B$22,-$B$21,IF(Y24>=W24*2,-$B$21*0.5,IF(W24>=Y24*2,$B$21*0.5,0))) -> 800 | Y24: =MAX(0,Y23+X23-Z23) -> 1200 | Z24: =IF(Y24<OFFSET(W24,-$B$17,0),Y24,OFFSET(W24,-$B$17,0)) -> 1200 | AA24: 22
E25: 23 | F25: =OFFSET(N25,-$B$5,0) -> 1300 | G25: =MAX(0,G24+(F24-H24)*$B$2) -> 3000 | H25: =MAX(0,IF(G25<$B$6,G25,IF(AND(G25>=$B$6+200,MOD(E25,4)=0),200+$B$6,$B$6))) -> 300 | I25: =MAX(0,($B$8-G25)+H25) -> 0 | J25: =MAX(0,I24-K24+J24) -> 0 | K25: =J25 -> 0 | L25: =OFFSET(T25,-$B$11,0) -> 900 | M25: =MAX(0,M24+(L24-N24)*$B$2) -> 2400 | N25: =IF(M25<OFFSET(K25,-$B$7,0),M25,OFFSET(K25,-$B$7,0)) -> 600 | O25: =MAX(0,$B$13-M25+N25) -> 0 | P25: =O24-Q24+P24 -> 600 | Q25: =P25 -> 600 | R25: =OFFSET(Z25,-$B$16,0) -> 800 | S25: =MAX(0,S24+(R24-T24)*$B$2) -> 800 | T25: =IF(S25<OFFSET(Q25,-$B$12,0),S25,OFFSET(Q25,-$B$12,0)) -> 800 | U25: =MAX(0,($B$18-S25)+T25) -> 2100 | V25: =U24+V24-W24 -> 2100 | W25: =V25 -> 2100 | X25: =$B$21+IF(Y25>=$B$22,-$B$21,IF(Y25>=W25*2,-$B$21*0.5,IF(W25>=Y25*2,$B$21*0.5,0))) -> 1200 | Y25: =MAX(0,Y24+X24-Z24) -> 800 | Z25: =IF(Y25<OFFSET(W25,-$B$17,0),Y25,OFFSET(W25,-$B$17,0)) -> 800 | AA25: 23
E26: 24 | F26: =OFFSET(N26,-$B$5,0) -> 1200 | G26: =MAX(0,G25+(F25-H25)*$B$2) -> 4000 | H26: =MAX(0,IF(G26<$B$6,G26,IF(AND(G26>=$B$6+200,MOD(E26,4)=0),200+$B$6,$B$6))) -> 500 | I26: =MAX(0,($B$8-G26)+H26) -> 0 | J26: =MAX(0,I25-K25+J25) -> 0 | K26: =J26 -> 0 | L26: =OFFSET(T26,-$B$11,0) -> 1200 | M26: =MAX(0,M25+(L25-N25)*$B$2) -> 2700 | N26: =IF(M26<OFFSET(K26,-$B$7,0),M26,OFFSET(K26,-$B$7,0)) -> 0 | O26: =MAX(0,$B$13-M26+N26) -> 0 | P26: =O25-Q25+P25 -> 0 | Q26: =P26 -> 0 | R26: =OFFSET(Z26,-$B$16,0) -> 1100 | S26: =MAX(0,S25+(R25-T25)*$B$2) -> 800 | T26: =IF(S26<OFFSET(Q26,-$B$12,0),S26,OFFSET(Q26,-$B$12,0)) -> 800 | U26: =MAX(0,($B$18-S26)+T26) -> 2100 | V26: =U25+V25-W25 -> 2100 | W26: =V26 -> 2100 | X26: =$B$21+IF(Y26>=$B$22,-$B$21,IF(Y26>=W26*2,-$B$21*0.5,IF(W26>=Y26*2,$B$21*0.5,0))) -> 800 | Y26: =MAX(0,Y25+X25-Z25) -> 1200 | Z26: =IF(Y26<OFFSET(W26,-$B$17,0),Y26,OFFSET(W26,-$B$17,0)) -> 1200 | AA26: 24
E27: 25 | F27: =OFFSET(N27,-$B$5,0) -> 600 | G27: =MAX(0,G26+(F26-H26)*$B$2) -> 4700 | H27: =MAX(0,IF(G27<$B$6,G27,IF(AND(G27>=$B$6+200,MOD(E27,4)=0),200+$B$6,$B$6))) -> 300 | I27: =MAX(0,($B$8-G27)+H27) -> 0 | J27: =MAX(0,I26-K26+J26) -> 0 | K27: =J27 -> 0 | L27: =OFFSET(T27,-$B$11,0) -> 800 | M27: =MAX(0,M26+(L26-N26)*$B$2) -> 3900 | N27: =IF(M27<OFFSET(K27,-$B$7,0),M27,OFFSET(K27,-$B$7,0)) -> 0 | O27: =MAX(0,$B$13-M27+N27) -> 0 | P27: =O26-Q26+P26 -> 0 | Q27: =P27 -> 0 | R27: =OFFSET(Z27,-$B$16,0) -> 900 | S27: =MAX(0,S26+(R26-T26)*$B$2) -> 1100 | T27: =IF(S27<OFFSET(Q27,-$B$12,0),S27,OFFSET(Q27,-$B$12,0)) -> 600 | U27: =MAX(0,($B$18-S27)+T27) -> 1600 | V27: =U26+V26-W26 -> 2100 | W27: =V27 -> 2100 | X27: =$B$21+IF(Y27>=$B$22,-$B$21,IF(Y27>=W27*2,-$B$21*0.5,IF(W27>=Y27*2,$B$21*0.5,0))) -> 1200 | Y27: =MAX(0,Y26+X26-Z26) -> 800 | Z27: =IF(Y27<OFFSET(W27,-$B$17,0),Y27,OFFSET(W27,-$B$17,0)) -> 800 | AA27: 25
E28: 26 | F28: =OFFSET(N28,-$B$5,0) -> 0 | G28: =MAX(0,G27+(F27-H27)*$B$2) -> 5000 | H28: =MAX(0,IF(G28<$B$6,G28,IF(AND(G28>=$B$6+200,MOD(E28,4)=0),200+$B$6,$B$6))) -> 300 | I28: =MAX(0,($B$8-G28)+H28) -> 0 | J28: =MAX(0,I27-K27+J27) -> 0 | K28: =J28 -> 0 | L28: =OFFSET(T28,-$B$11,0) -> 800 | M28: =MAX(0,M27+(L27-N27)*$B$2) -> 4700 | N28: =IF(M28<OFFSET(K28,-$B$7,0),M28,OFFSET(K28,-$B$7,0)) -> 0 | O28: =MAX(0,$B$13-M28+N28) -> 0 | P28: =O27-Q27+P27 -> 0 | Q28: =P28 -> 0 | R28: =OFFSET(Z28,-$B$16,0) -> 1200 | S28: =MAX(0,S27+(R27-T27)*$B$2) -> 1400 | T28: =IF(S28<OFFSET(Q28,-$B$12,0),S28,OFFSET(Q28,-$B$12,0)) -> 0 | U28: =MAX(0,($B$18-S28)+T28) -> 700 | V28: =U27+V27-W27 -> 1600 | W28: =V28 -> 1600 | X28: =$B$21+IF(Y28>=$B$22,-$B$21,IF(Y28>=W28*2,-$B$21*0.5,IF(W28>=Y28*2,$B$21*0.5,0))) -> 800 | Y28: =MAX(0,Y27+X27-Z27) -> 1200 | Z28: =IF(Y28<OFFSET(W28,-$B$17,0),Y28,OFFSET(W28,-$B$17,0)) -> 1200 | AA28: 26
E29: 27 | F29: =OFFSET(N29,-$B$5,0) -> 0 | G29: =MAX(0,G28+(F28-H28)*$B$2) -> 4700 | H29: =MAX(0,IF(G29<$B$6,G29,IF(AND(G29>=$B$6+200,MOD(E29,4)=0),200+$B$6,$B$6))) -> 300 | I29: =MAX(0,($B$8-G29)+H29) -> 0 | J29: =MAX(0,I28-K28+J28) -> 0 | K29: =J29 -> 0 | L29: =OFFSET(T29,-$B$11,0) -> 800 | M29: =MAX(0,M28+(L28-N28)*$B$2) -> 5500 | N29: =IF(M29<OFFSET(K29,-$B$7,0),M29,OFFSET(K29,-$B$7,0)) -> 0 | O29: =MAX(0,$B$13-M29+N29) -> 0 | P29: =O28-Q28+P28 -> 0 | Q29: =P29 -> 0 | R29: =OFFSET(Z29,-$B$16,0) -> 800 | S29: =MAX(0,S28+(R28-T28)*$B$2) -> 2600 | T29: =IF(S29<OFFSET(Q29,-$B$12,0),S29,OFFSET(Q29,-$B$12,0)) -> 0 | U29: =MAX(0,($B$18-S29)+T29) -> 0 | V29: =U28+V28-W28 -> 700 | W29: =V29 -> 700 | X29: =$B$21+IF(Y29>=$B$22,-$B$21,IF(Y29>=W29*2,-$B$21*0.5,IF(W29>=Y29*2,$B$21*0.5,0))) -> 800 | Y29: =MAX(0,Y28+X28-Z28) -> 800 | Z29: =IF(Y29<OFFSET(W29,-$B$17,0),Y29,OFFSET(W29,-$B$17,0)) -> 800 | AA29: 27
E30: 28 | F30: =OFFSET(N30,-$B$5,0) -> 0 | G30: =MAX(0,G29+(F29-H29)*$B$2) -> 4400 | H30: =MAX(0,IF(G30<$B$6,G30,IF(AND(G30>=$B$6+200,MOD(E30,4)=0),200+$B$6,$B$6))) -> 500 | I30: =MAX(0,($B$8-G30)+H30) -> 0 | J30: =MAX(0,I29-K29+J29) -> 0 | K30: =J30 -> 0 | L30: =OFFSET(T30,-$B$11,0) -> 600 | M30: =MAX(0,M29+(L29-N29)*$B$2) -> 6300 | N30: =IF(M30<OFFSET(K30,-$B$7,0),M30,OFFSET(K30,-$B$7,0)) -> 0 | O30: =MAX(0,$B$13-M30+N30) -> 0 | P30: =O29-Q29+P29 -> 0 | Q30: =P30 -> 0 | R30: =OFFSET(Z30,-$B$16,0) -> 1200 | S30: =MAX(0,S29+(R29-T29)*$B$2) -> 3400 | T30: =IF(S30<OFFSET(Q30,-$B$12,0),S30,OFFSET(Q30,-$B$12,0)) -> 0 | U30: =MAX(0,($B$18-S30)+T30) -> 0 | V30: =U29+V29-W29 -> 0 | W30: =V30 -> 0 | X30: =$B$21+IF(Y30>=$B$22,-$B$21,IF(Y30>=W30*2,-$B$21*0.5,IF(W30>=Y30*2,$B$21*0.5,0))) -> 400 | Y30: =MAX(0,Y29+X29-Z29) -> 800 | Z30: =IF(Y30<OFFSET(W30,-$B$17,0),Y30,OFFSET(W30,-$B$17,0)) -> 800 | AA30: 28
E31: 29 | F31: =OFFSET(N31,-$B$5,0) -> 0 | G31: =MAX(0,G30+(F30-H30)*$B$2) -> 3900 | H31: =MAX(0,IF(G31<$B$6,G31,IF(AND(G31>=$B$6+200,MOD(E31,4)=0),200+$B$6,$B$6))) -> 300 | I31: =MAX(0,($B$8-G31)+H31) -> 0 | J31: =MAX(0,I30-K30+J30) -> 0 | K31: =J31 -> 0 | L31: =OFFSET(T31,-$B$11,0) -> 0 | M31: =MAX(0,M30+(L30-N30)*$B$2) -> 6900 | N31: =IF(M31<OFFSET(K31,-$B$7,0),M31,OFFSET(K31,-$B$7,0)) -> 0 | O31: =MAX(0,$B$13-M31+N31) -> 0 | P31: =O30-Q30+P30 -> 0 | Q31: =P31 -> 0 | R31: =OFFSET(Z31,-$B$16,0) -> 800 | S31: =MAX(0,S30+(R30-T30)*$B$2) -> 4600 | T31: =IF(S31<OFFSET(Q31,-$B$12,0),S31,OFFSET(Q31,-$B$12,0)) -> 0 | U31: =MAX(0,($B$18-S31)+T31) -> 0 | V31: =U30+V30-W30 -> 0 | W31: =V31 -> 0 | X31: =$B$21+IF(Y31>=$B$22,-$B$21,IF(Y31>=W31*2,-$B$21*0.5,IF(W31>=Y31*2,$B$21*0.5,0))) -> 400 | Y31: =MAX(0,Y30+X30-Z30) -> 400 | Z31: =IF(Y31<OFFSET(W31,-$B$17,0),Y31,OFFSET(W31,-$B$17,0)) -> 400 | AA31: 29
E32: 30 | F32: =OFFSET(N32,-$B$5,0) -> 0 | G32: =MAX(0,G31+(F31-H31)*$B$2) -> 3600 | H32: =MAX(0,IF(G32<$B$6,G32,IF(AND(G32>=$B$6+200,MOD(E32,4)=0),200+$B$6,$B$6))) -> 300 | I32: =MAX(0,($B$8-G32)+H32) -> 0 | J32: =MAX(0,I31-K31+J31) -> 0 | K32: =J32 -> 0 | L32: =OFFSET(T32,-$B$11,0) -> 0 | M32: =MAX(0,M31+(L31-N31)*$B$2) -> 6900 | N32: =IF(M32<OFFSET(K32,-$B$7,0),M32,OFFSET(K32,-$B$7,0)) -> 0 | O32: =MAX(0,$B$13-M32+N32) -> 0 | P32: =O31-Q31+P31 -> 0 | Q32: =P32 -> 0 | R32: =OFFSET(Z32,-$B$16,0) -> 1200 | S32: =MAX(0,S31+(R31-T31)*$B$2) -> 5400 | T32: =IF(S32<OFFSET(Q32,-$B$12,0),S32,OFFSET(Q32,-$B$12,0)) -> 0 | U32: =MAX(0,($B$18-S32)+T32) -> 0 | V32: =U31+V31-W31 -> 0 | W32: =V32 -> 0 | X32: =$B$21+IF(Y32>=$B$22,-$B$21,IF(Y32>=W32*2,-$B$21*0.5,IF(W32>=Y32*2,$B$21*0.5,0))) -> 400 | Y32: =MAX(0,Y31+X31-Z31) -> 400 | Z32: =IF(Y32<OFFSET(W32,-$B$17,0),Y32,OFFSET(W32,-$B$17,0)) -> 400 | AA32: 30
E33: 31 | F33: =OFFSET(N33,-$B$5,0) -> 0 | G33: =MAX(0,G32+(F32-H32)*$B$2) -> 3300 | H33: =MAX(0,IF(G33<$B$6,G33,IF(AND(G33>=$B$6+200,MOD(E33,4)=0),200+$B$6,$B$6))) -> 300 | I33: =MAX(0,($B$8-G33)+H33) -> 0 | J33: =MAX(0,I32-K32+J32) -> 0 | K33: =J33 -> 0 | L33: =OFFSET(T33,-$B$11,0) -> 0 | M33: =MAX(0,M32+(L32-N32)*$B$2) -> 6900 | N33: =IF(M33<OFFSET(K33,-$B$7,0),M33,OFFSET(K33,-$B$7,0)) -> 0 | O33: =MAX(0,$B$13-M33+N33) -> 0 | P33: =O32-Q32+P32 -> 0 | Q33: =P33 -> 0 | R33: =OFFSET(Z33,-$B$16,0) -> 800 | S33: =MAX(0,S32+(R32-T32)*$B$2) -> 6600 | T33: =IF(S33<OFFSET(Q33,-$B$12,0),S33,OFFSET(Q33,-$B$12,0)) -> 0 | U33: =MAX(0,($B$18-S33)+T33) -> 0 | V33: =U32+V32-W32 -> 0 | W33: =V33 -> 0 | X33: =$B$21+IF(Y33>=$B$22,-$B$21,IF(Y33>=W33*2,-$B$21*0.5,IF(W33>=Y33*2,$B$21*0.5,0))) -> 400 | Y33: =MAX(0,Y32+X32-Z32) -> 400 | Z33: =IF(Y33<OFFSET(W33,-$B$17,0),Y33,OFFSET(W33,-$B$17,0)) -> 0 | AA33: 31
E34: 32 | F34: =OFFSET(N34,-$B$5,0) -> 0 | G34: =MAX(0,G33+(F33-H33)*$B$2) -> 3000 | H34: =MAX(0,IF(G34<$B$6,G34,IF(AND(G34>=$B$6+200,MOD(E34,4)=0),200+$B$6,$B$6))) -> 500 | I34: =MAX(0,($B$8-G34)+H34) -> 0 | J34: =MAX(0,I33-K33+J33) -> 0 | K34: =J34 -> 0 | L34: =OFFSET(T34,-$B$11,0) -> 0 | M34: =MAX(0,M33+(L33-N33)*$B$2) -> 6900 | N34: =IF(M34<OFFSET(K34,-$B$7,0),M34,OFFSET(K34,-$B$7,0)) -> 0 | O34: =MAX(0,$B$13-M34+N34) -> 0 | P34: =O33-Q33+P33 -> 0 | Q34: =P34 -> 0 | R34: =OFFSET(Z34,-$B$16,0) -> 800 | S34: =MAX(0,S33+(R33-T33)*$B$2) -> 7400 | T34: =IF(S34<OFFSET(Q34,-$B$12,0),S34,OFFSET(Q34,-$B$12,0)) -> 0 | U34: =MAX(0,($B$18-S34)+T34) -> 0 | V34: =U33+V33-W33 -> 0 | W34: =V34 -> 0 | X34: =$B$21+IF(Y34>=$B$22,-$B$21,IF(Y34>=W34*2,-$B$21*0.5,IF(W34>=Y34*2,$B$21*0.5,0))) -> 400 | Y34: =MAX(0,Y33+X33-Z33) -> 800 | Z34: =IF(Y34<OFFSET(W34,-$B$17,0),Y34,OFFSET(W34,-$B$17,0)) -> 0 | AA34: 32
... E402: 400 | F402: =OFFSET(N402,-$B$5,0) -> 1100 | G402: =MAX(0,G401+(F401-H401)*$B$2) -> 600 | H402: =MAX(0,IF(G402<$B$6,G402,IF(AND(G402>=$B$6+200,MOD(E402,4)=0),200+$B$6,$B$6))) -> 500 | I402: =MAX(0,($B$8-G402)+H402) -> 1200 | J402: =MAX(0,I401-K401+J401) -> 1300 | K402: =J402 -> 1300 | L402: =OFFSET(T402,-$B$11,0) -> 0 | M402: =MAX(0,M401+(L401-N401)*$B$2) -> 200 | N402: =IF(M402<OFFSET(K402,-$B$7,0),M402,OFFSET(K402,-$B$7,0)) -> 200 | O402: =MAX(0,$B$13-M402+N402) -> 1500 | P402: =O401-Q401+P401 -> 1300 | Q402: =P402 -> 1300 | R402: =OFFSET(Z402,-$B$16,0) -> 2000 | S402: =MAX(0,S401+(R401-T401)*$B$2) -> 500 | T402: =IF(S402<OFFSET(Q402,-$B$12,0),S402,OFFSET(Q402,-$B$12,0)) -> 0 | U402: =MAX(0,($B$18-S402)+T402) -> 1600 | V402: =U401+V401-W401 -> 2100 | W402: =V402 -> 2100 | X402: =$B$21+IF(Y402>=$B$22,-$B$21,IF(Y402>=W402*2,-$B$21*0.5,IF(W402>=Y402*2,$B$21*0.5,0))) -> 800 | Y402: =MAX(0,Y401+X401-Z401) -> 2800 | Z402: =IF(Y402<OFFSET(W402,-$B$17,0),Y402,OFFSET(W402,-$B$17,0)) -> 2100 | AA402: 400
F404: =SUM(F2:F402) -> 128300 | L404: =SUM(L2:L402) -> 128600 | N404: =SUM(N2:N402) -> 129800 | R404: =SUM(R2:R402) -> 129300 | T404: =SUM(T2:T402) -> 128600 | Z404: =SUM(Z2:Z402) -> 137700

Sheet Model SSD_2
A1: Model SSD_2 with limits | F1: Incoming goods Retail, Unit/ Week | G1: Warehouse Retail, Unit | H1: Outgoing goods Retail, Unit/ Week | I1: Orders Retail, Unit/ Week | J1: Placed orders Retail, Unit | K1: Outgoing orders Retail, Unit/ Week | L1: Incoming goods Wholesale, Unit/ Week | M1: Warehouse Wholesale, Unit | N1: Outgoing goods Wholesale, Unit/ Week | O1: Orders Wholesale, Unit/ Week | P1: Placed orders Wholesale, Unit | Q1: Outgoing orders Wholesale, Unit/ Week | R1: Incoming goods RWH, Unit/ Week | S1: Warehouse RWH, Unit | T1: Outgoing goods RWH, Unit/ Week | U1: Orders RWH, Unit/ Week | V1: Placed orders RWH, Unit | W1: Outgoing orders RWH, Unit/ Week | X1: Production Factory, Unit/ Week | Y1: Warehouse Factory, Unit | Z1: Outgoing goods Factory, Unit/ Week
A2: TIME STEP | B2: 1 | C2: Week | E2: 0 | F2: 0 | G2: =B4 -> 900 | H2: 0 | I2: 0 | J2: 0 | K2: =IF(J2>=$B$14,$B$14,0) -> 0 | L2: 0 | M2: =B10 -> 1200 | N2: 0 | O2: 0 | P2: 0 | Q2: =IF(P2>=$B$20,$B$20,0) -> 0 | R2: 0 | S2: =B16 -> 1800 | T2: =O2 -> 0 | U2: 0 | V2: 0 | W2: =IF(V2>=$B$24,$B$24,0) -> 0 | X2: 0 | Y2: =$B$22 -> 2400 | Z2: 0 | AA2: 0
E3: 1 | F3: 0 | G3: =MAX(0,G2+(F2-H2)*$B$2) -> 900 | H3: =MAX(0,IF(G3<$B$6,G3,IF(AND(G3>=$B$6+200,MOD(E3,4)=0),200+$B$6,$B$6))) -> 300 | I3: =MAX(0,($B$8-G3)+H3) -> 700 | J3: =MAX(0,I2-K2+J2) -> 0 | K3: =IF(J3>=$B$14,$B$14,0) -> 0 | L3: 0 | M3: =MAX(0,M2+(L2-N2)*$B$2) -> 1200 | N3: =IF(AND(M3>=$B$14,OFFSET(K3,-$B$7,0)>=$B$14),$B$14,0) -> 0 | O3: =MAX(0,$B$13-M3+N3) -> 300 | P3: =O2-Q2+P2 -> 0 | Q3: =IF(P3>=$B$20,$B$20,0) -> 0 | R3: 0 | S3: =MAX(0,S2+(R2-T2)*$B$2) -> 1800 | T3: 0 | U3: =MAX(0,($B$19-S3)+T3) -> 300 | V3: =U2+V2-W2 -> 0 | W3: =IF(V3>=$B$24,$B$24,0) -> 0 | X3: =$B$23+IF(Y3>=$B$25,-$B$23,IF(Y3>=W3*2,-$B$23*0.5,IF(W3>=Y3*2,$B$23*0.5,0))) -> 400 | Y3: =MAX(0,Y2+X2-Z2) -> 2400 | Z3: 0 | AA3: 1
A4: Initial supply Retail | B4: 900 | C4: Unit | E4: 2 | F4: =OFFSET(N4,-$B$5,0) -> 0 | G4: =MAX(0,G3+(F3-H3)*$B$2) -> 600 | H4: =MAX(0,IF(G4<$B$6,G4,IF(AND(G4>=$B$6+200,MOD(E4,4)=0),200+$B$6,$B$6))) -> 300 | I4: =MAX(0,($B$8-G4)+H4) -> 1000 | J4: =MAX(0,I3-K3+J3) -> 700 | K4: =IF(J4>=$B$14,$B$14,0) -> 0 | L4: 0 | M4: =MAX(0,M3+(L3-N3)*$B$2) -> 1200 | N4: =IF(AND(M4>=$B$14,OFFSET(K4,-$B$7,0)>=$B$14),$B$14,0) -> 0 | O4: =MAX(0,$B$13-M4+N4) -> 300 | P4: =O3-Q3+P3 -> 300 | Q4: =IF(P4>=$B$20,$B$20,0) -> 0 | R4: 0 | S4: =MAX(0,S3+(R3-T3)*$B$2) -> 1800 | T4: =IF(AND(S4>=$B$20,OFFSET(Q4,-$B$12,0)>=$B$20),$B$20,0) -> 0 | U4: =MAX(0,($B$19-S4)+T4) -> 300 | V4: =U3+V3-W3 -> 300 | W4: =IF(V4>=$B$24,$B$24,0) -> 0 | X4: =$B$23+IF(Y4>=$B$25,-$B$23,IF(Y4>=W4*2,-$B$23*0.5,IF(W4>=Y4*2,$B$23*0.5,0))) -> 400 | Y4: =MAX(0,Y3+X3-Z3) -> 2800 | Z4: 0 | AA4: 2
A5: Delivery time to Retail | B5: 2 | C5: Week | E5: 3 | F5: =OFFSET(N5,-$B$5,0) -> 0 | G5: =MAX(0,G4+(F4-H4)*$B$2) -> 300 | H5: =MAX(0,IF(G5<$B$6,G5,IF(AND(G5>=$B$6+200,MOD(E5,4)=0),200+$B$6,$B$6))) -> 300 | I5: =MAX(0,($B$8-G5)+H5) -> 1300 | J5: =MAX(0,I4-K4+J4) -> 1700 | K5: =IF(J5>=$B$14,$B$14,0) -> 1000 | L5: =OFFSET(T5,-$B$11,0) -> 0 | M5: =MAX(0,M4+(L4-N4)*$B$2) -> 1200 | N5: =IF(AND(M5>=$B$14,OFFSET(K5,-$B$7,0)>=$B$14),$B$14,0) -> 0 | O5: =MAX(0,$B$13-M5+N5) -> 300 | P5: =O4-Q4+P4 -> 600 | Q5: =IF(P5>=$B$20,$B$20,0) -> 0 | R5: 0 | S5: =MAX(0,S4+(R4-T4)*$B$2) -> 1800 | T5: =IF(AND(S5>=$B$20,OFFSET(Q5,-$B$12,0)>=$B$20),$B$20,0) -> 0 | U5: =MAX(0,($B$19-S5)+T5) -> 300 | V5: =U4+V4-W4 -> 600 | W5: =IF(V5>=$B$24,$B$24,0) -> 0 | X5: =$B$23+IF(Y5>=$B$25,-$B$23,IF(Y5>=W5*2,-$B$23*0.5,IF(W5>=Y5*2,$B$23*0.5,0))) -> 400 | Y5: =MAX(0,Y4+X4-Z4) -> 3200 | Z5: =IF(AND(Y5>=$B$24,OFFSET(W5,-$B$18,0)>=$B$24),$B$24,0) -> 0 | AA5: 3
A6: Average amount of sales Retail | B6: 300 | C6: Unit/ Week | E6: 4 | F6: =OFFSET(N6,-$B$5,0) -> 0 | G6: =MAX(0,G5+(F5-H5)*$B$2) -> 0 | H6: =MAX(0,IF(G6<$B$6,G6,IF(AND(G6>=$B$6+200,MOD(E6,4)=0),200+$B$6,$B$6))) -> 0 | I6: =MAX(0,($B$8-G6)+H6) -> 1300 | J6: =MAX(0,I5-K5+J5) -> 2000 | K6: =IF(J6>=$B$14,$B$14,0) -> 1000 | L6: 0 | M6: =MAX(0,M5+(L5-N5)*$B$2) -> 1200 | N6: =IF(AND(M6>=$B$14,OFFSET(K6,-$B$7,0)>=$B$14),$B$14,0) -> 1000 | O6: =MAX(0,$B$13-M6+N6) -> 1300 | P6: =O5-Q5+P5 -> 900 | Q6: =IF(P6>=$B$20,$B$20,0) -> 0 | R6: =OFFSET(Z6,-$B$17,0) -> 0 | S6: =MAX(0,S5+(R5-T5)*$B$2) -> 1800 | T6: =IF(AND(S6>=$B$20,OFFSET(Q6,-$B$12,0)>=$B$20),$B$20,0) -> 0 | U6: =MAX(0,($B$19-S6)+T6) -> 300 | V6: =U5+V5-W5 -> 900 | W6: =IF(V6>=$B$24,$B$24,0) -> 0 | X6: =$B$23+IF(Y6>=$B$25,-$B$23,IF(Y6>=W6*2,-$B$23*0.5,IF(W6>=Y6*2,$B$23*0.5,0))) -> 400 | Y6: =MAX(0,Y5+X5-Z5) -> 3600 | Z6: =IF(AND(Y6>=$B$24,OFFSET(W6,-$B$18,0)>=$B$24),$B$24,0) -> 0 | AA6: 4
A7: Time to fill oder for Retail | B7: 1 | C7: Week | E7: 5 | F7: =OFFSET(N7,-$B$5,0) -> 0 | G7: =MAX(0,G6+(F6-H6)*$B$2) -> 0 | H7: =MAX(0,IF(G7<$B$6,G7,IF(AND(G7>=$B$6+200,MOD(E7,4)=0),200+$B$6,$B$6))) -> 0 | I7: =MAX(0,($B$8-G7)+H7) -> 1300 | J7: =MAX(0,I6-K6+J6) -> 2300 | K7: =IF(J7>=$B$14,$B$14,0) -> 1000 | L7: =OFFSET(T7,-$B$11,0) -> 0 | M7: =MAX(0,M6+(L6-N6)*$B$2) -> 200 | N7: =IF(AND(M7>=$B$14,OFFSET(K7,-$B$7,0)>=$B$14),$B$14,0) -> 0 | O7: =MAX(0,$B$13-M7+N7) -> 1300 | P7: =O6-Q6+P6 -> 2200 | Q7: =IF(P7>=$B$20,$B$20,0) -> 1500 | R7: =OFFSET(Z7,-$B$17,0) -> 0 | S7: =MAX(0,S6+(R6-T6)*$B$2) -> 1800 | T7: =IF(AND(S7>=$B$20,OFFSET(Q7,-$B$12,0)>=$B$20),$B$20,0) -> 0 | U7: =MAX(0,($B$19-S7)+T7) -> 300 | V7: =U6+V6-W6 -> 1200 | W7: =IF(V7>=$B$24,$B$24,0) -> 0 | X7: =$B$23+IF(Y7>=$B$25,-$B$23,IF(Y7>=W7*2,-$B$23*0.5,IF(W7>=Y7*2,$B$23*0.5,0))) -> 400 | Y7: =MAX(0,Y6+X6-Z6) -> 4000 | Z7: =IF(AND(Y7>=$B$24,OFFSET(W7,-$B$18,0)>=$B$24),$B$24,0) -> 0 | AA7: 5
A8: Desired supply Retail | B8: 1300 | C8: Unit | E8: 6 | F8: =OFFSET(N8,-$B$5,0) -> 1000 | G8: =MAX(0,G7+(F7-H7)*$B$2) -> 0 | H8: =MAX(0,IF(G8<$B$6,G8,IF(AND(G8>=$B$6+200,MOD(E8,4)=0),200+$B$6,$B$6))) -> 0 | I8: =MAX(0,($B$8-G8)+H8) -> 1300 | J8: =MAX(0,I7-K7+J7) -> 2600 | K8: =IF(J8>=$B$14,$B$14,0) -> 1000 | L8: =OFFSET(T8,-$B$11,0) -> 0 | M8: =MAX(0,M7+(L7-N7)*$B$2) -> 200 | N8: =IF(AND(M8>=$B$14,OFFSET(K8,-$B$7,0)>=$B$14),$B$14,0) -> 0 | O8: =MAX(0,$B$13-M8+N8) -> 1300 | P8: =O7-Q7+P7 -> 2000 | Q8: =IF(P8>=$B$20,$B$20,0) -> 1500 | R8: =OFFSET(Z8,-$B$17,0) -> 0 | S8: =MAX(0,S7+(R7-T7)*$B$2) -> 1800 | T8: =IF(AND(S8>=$B$20,OFFSET(Q8,-$B$12,0)>=$B$20),$B$20,0) -> 0 | U8: =MAX(0,($B$19-S8)+T8) -> 300 | V8: =U7+V7-W7 -> 1500 | W8: =IF(V8>=$B$24,$B$24,0) -> 0 | X8: =$B$23+IF(Y8>=$B$25,-$B$23,IF(Y8>=W8*2,-$B$23*0.5,IF(W8>=Y8*2,$B$23*0.5,0))) -> 400 | Y8: =MAX(0,Y7+X7-Z7) -> 4400 | Z8: =IF(AND(Y8>=$B$24,OFFSET(W8,-$B$18,0)>=$B$24),$B$24,0) -> 0 | AA8: 6
E9: 7 | F9: =OFFSET(N9,-$B$5,0) -> 0 | G9: =MAX(0,G8+(F8-H8)*$B$2) -> 1000 | H9: =MAX(0,IF(G9<$B$6,G9,IF(AND(G9>=$B$6+200,MOD(E9,4)=0),200+$B$6,$B$6))) -> 300 | I9: =MAX(0,($B$8-G9)+H9) -> 600 | J9: =MAX(0,I8-K8+J8) -> 2900 | K9: =IF(J9>=$B$14,$B$14,0) -> 1000 | L9: =OFFSET(T9,-$B$11,0) -> 0 | M9: =MAX(0,M8+(L8-N8)*$B$2) -> 200 | N9: =IF(AND(M9>=$B$14,OFFSET(K9,-$B$7,0)>=$B$14),$B$14,0) -> 0 | O9: =MAX(0,$B$13-M9+N9) -> 1300 | P9: =O8-Q8+P8 -> 1800 | Q9: =IF(P9>=$B$20,$B$20,0) -> 1500 | R9: =OFFSET(Z9,-$B$17,0) -> 0 | S9: =MAX(0,S8+(R8-T8)*$B$2) -> 1800 | T9: =IF(AND(S9>=$B$20,OFFSET(Q9,-$B$12,0)>=$B$20),$B$20,0) -> 1500 | U9: =MAX(0,($B$19-S9)+T9) -> 1800 | V9: =U8+V8-W8 -> 1800 | W9: =IF(V9>=$B$24,$B$24,0) -> 0 | X9: =$B$23+IF(Y9>=$B$25,-$B$23,IF(Y9>=W9*2,-$B$23*0.5,IF(W9>=Y9*2,$B$23*0.5,0))) -> 400 | Y9: =MAX(0,Y8+X8-Z8) -> 4800 | Z9: =IF(AND(Y9>=$B$24,OFFSET(W9,-$B$18,0)>=$B$24),$B$24,0) -> 0 | AA9: 7
A10: Initial supply Wholesale | B10: 1200 | C10: Unit | E10: 8 | F10: =OFFSET(N10,-$B$5,0) -> 0 | G10: =MAX(0,G9+(F9-H9)*$B$2) -> 700 | H10: =MAX(0,IF(G10<$B$6,G10,IF(AND(G10>=$B$6+200,MOD(E10,4)=0),200+$B$6,$B$6))) -> 500 | I10: =MAX(0,($B$8-G10)+H10) -> 1100 | J10: =MAX(0,I9-K9+J9) -> 2500 | K10: =IF(J10>=$B$14,$B$14,0) -> 1000 | L10: =OFFSET(T10,-$B$11,0) -> 0 | M10: =MAX(0,M9+(L9-N9)*$B$2) -> 200 | N10: =IF(AND(M10>=$B$14,OFFSET(K10,-$B$7,0)>=$B$14),$B$14,0) -> 0 | O10: =MAX(0,$B$13-M10+N10) -> 1300 | P10: =O9-Q9+P9 -> 1600 | Q10: =IF(P10>=$B$20,$B$20,0) -> 1500 | R10: =OFFSET(Z10,-$B$17,0) -> 0 | S10: =MAX(0,S9+(R9-T9)*$B$2) -> 300 | T10: =IF(AND(S10>=$B$20,OFFSET(Q10,-$B$12,0)>=$B$20),$B$20,0) -> 0 | U10: =MAX(0,($B$19-S10)+T10) -> 1800 | V10: =U9+V9-W9 -> 3600 | W10: =IF(V10>=$B$24,$B$24,0) -> 2000 | X10: =$B$23+IF(Y10>=$B$25,-$B$23,IF(Y10>=W10*2,-$B$23*0.5,IF(W10>=Y10*2,$B$23*0.5,0))) -> 400 | Y10: =MAX(0,Y9+X9-Z9) -> 5200 | Z10: =IF(AND(Y10>=$B$24,OFFSET(W10,-$B$18,0)>=$B$24),$B$24,0) -> 0 | AA10: 8
A11: Delivery time to Wholesale | B11: 3 | C11: Week | E11: 9 | F11: =OFFSET(N11,-$B$5,0) -> 0 | G11: =MAX(0,G10+(F10-H10)*$B$2) -> 200 | H11: =MAX(0,IF(G11<$B$6,G11,IF(AND(G11>=$B$6+200,MOD(E11,4)=0),200+$B$6,$B$6))) -> 200 | I11: =MAX(0,($B$8-G11)+H11) -> 1300 | J11: =MAX(0,I10-K10+J10) -> 2600 | K11: =IF(J11>=$B$14,$B$14,0) -> 1000 | L11: =OFFSET(T11,-$B$11,0) -> 0 | M11: =MAX(0,M10+(L10-N10)*$B$2) -> 200 | N11: =IF(AND(M11>=$B$14,OFFSET(K11,-$B$7,0)>=$B$14),$B$14,0) -> 0 | O11: =MAX(0,$B$13-M11+N11) -> 1300 | P11: =O10-Q10+P10 -> 1400 | Q11: =IF(P11>=$B$20,$B$20,0) -> 0 | R11: =OFFSET(Z11,-$B$17,0) -> 0 | S11: =MAX(0,S10+(R10-T10)*$B$2) -> 300 | T11: =IF(AND(S11>=$B$20,OFFSET(Q11,-$B$12,0)>=$B$20),$B$20,0) -> 0 | U11: =MAX(0,($B$19-S11)+T11) -> 1800 | V11: =U10+V10-W10 -> 3400 | W11: =IF(V11>=$B$24,$B$24,0) -> 2000 | X11: =$B$23+IF(Y11>=$B$25,-$B$23,IF(Y11>=W11*2,-$B$23*0.5,IF(W11>=Y11*2,$B$23*0.5,0))) -> 400 | Y11: =MAX(0,Y10+X10-Z10) -> 5600 | Z11: =IF(AND(Y11>=$B$24,OFFSET(W11,-$B$18,0)>=$B$24),$B$24,0) -> 0 | AA11: 9
A12: Time to fill oder for Wholesale | B12: 2 | C12: Week | E12: 10 | F12: =OFFSET(N12,-$B$5,0) -> 0 | G12: =MAX(0,G11+(F11-H11)*$B$2) -> 0 | H12: =MAX(0,IF(G12<$B$6,G12,IF(AND(G12>=$B$6+200,MOD(E12,4)=0),200+$B$6,$B$6))) -> 0 | I12: =MAX(0,($B$8-G12)+H12) -> 1300 | J12: =MAX(0,I11-K11+J11) -> 2900 | K12: =IF(J12>=$B$14,$B$14,0) -> 1000 | L12: =OFFSET(T12,-$B$11,0) -> 1500 | M12: =MAX(0,M11+(L11-N11)*$B$2) -> 200 | N12: =IF(AND(M12>=$B$14,OFFSET(K12,-$B$7,0)>=$B$14),$B$14,0) -> 0 | O12: =MAX(0,$B$13-M12+N12) -> 1300 | P12: =O11-Q11+P11 -> 2700 | Q12: =IF(P12>=$B$20,$B$20,0) -> 1500 | R12: =OFFSET(Z12,-$B$17,0) -> 0 | S12: =MAX(0,S11+(R11-T11)*$B$2) -> 300 | T12: =IF(AND(S12>=$B$20,OFFSET(Q12,-$B$12,0)>=$B$20),$B$20,0) -> 0 | U12: =MAX(0,($B$19-S12)+T12) -> 1800 | V12: =U11+V11-W11 -> 3200 | W12: =IF(V12>=$B$24,$B$24,0) -> 2000 | X12: =$B$23+IF(Y12>=$B$25,-$B$23,IF(Y12>=W12*2,-$B$23*0.5,IF(W12>=Y12*2,$B$23*0.5,0))) -> 400 | Y12: =MAX(0,Y11+X11-Z11) -> 6000 | Z12: =IF(AND(Y12>=$B$24,OFFSET(W12,-$B$18,0)>=$B$24),$B$24,0) -> 0 | AA12: 10
A13: Desired supply Wholesale | B13: 1500 | C13: Unit | E13: 11 | F13: =OFFSET(N13,-$B$5,0) -> 0 | G13: =MAX(0,G12+(F12-H12)*$B$2) -> 0 | H13: =MAX(0,IF(G13<$B$6,G13,IF(AND(G13>=$B$6+200,MOD(E13,4)=0),200+$B$6,$B$6))) -> 0 | I13: =MAX(0,($B$8-G13)+H13) -> 1300 | J13: =MAX(0,I12-K12+J12) -> 3200 | K13: =IF(J13>=$B$14,$B$14,0) -> 1000 | L13: =OFFSET(T13,-$B$11,0) -> 0 | M13: =MAX(0,M12+(L12-N12)*$B$2) -> 1700 | N13: =IF(AND(M13>=$B$14,OFFSET(K13,-$B$7,0)>=$B$14),$B$14,0) -> 1000 | O13: =MAX(0,$B$13-M13+N13) -> 800 | P13: =O12-Q12+P12 -> 2500 | Q13: =IF(P13>=$B$20,$B$20,0) -> 1500 | R13: =OFFSET(Z13,-$B$17,0) -> 0 | S13: =MAX(0,S12+(R12-T12)*$B$2) -> 300 | T13: =IF(AND(S13>=$B$20,OFFSET(Q13,-$B$12,0)>=$B$20),$B$20,0) -> 0 | U13: =MAX(0,($B$19-S13)+T13) -> 1800 | V13: =U12+V12-W12 -> 3000 | W13: =IF(V13>=$B$24,$B$24,0) -> 2000 | X13: =$B$23+IF(Y13>=$B$25,-$B$23,IF(Y13>=W13*2,-$B$23*0.5,IF(W13>=Y13*2,$B$23*0.5,0))) -> 400 | Y13: =MAX(0,Y12+X12-Z12) -> 6400 | Z13: =IF(AND(Y13>=$B$24,OFFSET(W13,-$B$18,0)>=$B$24),$B$24,0) -> 2000 | AA13: 11
A14: Min order size of Wholesale | B14: 1000 | C14: Unit | E14: 12 | F14: =OFFSET(N14,-$B$5,0) -> 0 | G14: =MAX(0,G13+(F13-H13)*$B$2) -> 0 | H14: =MAX(0,IF(G14<$B$6,G14,IF(AND(G14>=$B$6+200,MOD(E14,4)=0),200+$B$6,$B$6))) -> 0 | I14: =MAX(0,($B$8-G14)+H14) -> 1300 | J14: =MAX(0,I13-K13+J13) -> 3500 | K14: =IF(J14>=$B$14,$B$14,0) -> 1000 | L14: =OFFSET(T14,-$B$11,0) -> 0 | M14: =MAX(0,M13+(L13-N13)*$B$2) -> 700 | N14: =IF(AND(M14>=$B$14,OFFSET(K14,-$B$7,0)>=$B$14),$B$14,0) -> 0 | O14: =MAX(0,$B$13-M14+N14) -> 800 | P14: =O13-Q13+P13 -> 1800 | Q14: =IF(P14>=$B$20,$B$20,0) -> 1500 | R14: =OFFSET(Z14,-$B$17,0) -> 0 | S14: =MAX(0,S13+(R13-T13)*$B$2) -> 300 | T14: =IF(AND(S14>=$B$20,OFFSET(Q14,-$B$12,0)>=$B$20),$B$20,0) -> 0 | U14: =MAX(0,($B$19-S14)+T14) -> 1800 | V14: =U13+V13-W13 -> 2800 | W14: =IF(V14>=$B$24,$B$24,0) -> 2000 | X14: =$B$23+IF(Y14>=$B$25,-$B$23,IF(Y14>=W14*2,-$B$23*0.5,IF(W14>=Y14*2,$B$23*0.5,0))) -> 400 | Y14: =MAX(0,Y13+X13-Z13) -> 4800 | Z14: =IF(AND(Y14>=$B$24,OFFSET(W14,-$B$18,0)>=$B$24),$B$24,0) -> 2000 | AA14: 12
E15: 13 | F15: =OFFSET(N15,-$B$5,0) -> 1000 | G15: =MAX(0,G14+(F14-H14)*$B$2) -> 0 | H15: =MAX(0,IF(G15<$B$6,G15,IF(AND(G15>=$B$6+200,MOD(E15,4)=0),200+$B$6,$B$6))) -> 0 | I15: =MAX(0,($B$8-G15)+H15) -> 1300 | J15: =MAX(0,I14-K14+J14) -> 3800 | K15: =IF(J15>=$B$14,$B$14,0) -> 1000 | L15: =OFFSET(T15,-$B$11,0) -> 0 | M15: =MAX(0,M14+(L14-N14)*$B$2) -> 700 | N15: =IF(AND(M15>=$B$14,OFFSET(K15,-$B$7,0)>=$B$14),$B$14,0) -> 0 | O15: =MAX(0,$B$13-M15+N15) -> 800 | P15: =O14-Q14+P14 -> 1100 | Q15: =IF(P15>=$B$20,$B$20,0) -> 0 | R15: =OFFSET(Z15,-$B$17,0) -> 0 | S15: =MAX(0,S14+(R14-T14)*$B$2) -> 300 | T15: =IF(AND(S15>=$B$20,OFFSET(Q15,-$B$12,0)>=$B$20),$B$20,0) -> 0 | U15: =MAX(0,($B$19-S15)+T15) -> 1800 | V15: =U14+V14-W14 -> 2600 | W15: =IF(V15>=$B$24,$B$24,0) -> 2000 | X15: =$B$23+IF(Y15>=$B$25,-$B$23,IF(Y15>=W15*2,-$B$23*0.5,IF(W15>=Y15*2,$B$23*0.5,0))) -> 800 | Y15: =MAX(0,Y14+X14-Z14) -> 3200 | Z15: =IF(AND(Y15>=$B$24,OFFSET(W15,-$B$18,0)>=$B$24),$B$24,0) -> 2000 | AA15: 13
A16: Initial supply Regional Warehouse | B16: 1800 | C16: Unit | E16: 14 | F16: =OFFSET(N16,-$B$5,0) -> 0 | G16: =MAX(0,G15+(F15-H15)*$B$2) -> 1000 | H16: =MAX(0,IF(G16<$B$6,G16,IF(AND(G16>=$B$6+200,MOD(E16,4)=0),200+$B$6,$B$6))) -> 300 | I16: =MAX(0,($B$8-G16)+H16) -> 600 | J16: =MAX(0,I15-K15+J15) -> 4100 | K16: =IF(J16>=$B$14,$B$14,0) -> 1000 | L16: =OFFSET(T16,-$B$11,0) -> 0 | M16: =MAX(0,M15+(L15-N15)*$B$2) -> 700 | N16: =IF(AND(M16>=$B$14,OFFSET(K16,-$B$7,0)>=$B$14),$B$14,0) -> 0 | O16: =MAX(0,$B$13-M16+N16) -> 800 | P16: =O15-Q15+P15 -> 1900 | Q16: =IF(P16>=$B$20,$B$20,0) -> 1500 | R16: =OFFSET(Z16,-$B$17,0) -> 0 | S16: =MAX(0,S15+(R15-T15)*$B$2) -> 300 | T16: =IF(AND(S16>=$B$20,OFFSET(Q16,-$B$12,0)>=$B$20),$B$20,0) -> 0 | U16: =MAX(0,($B$19-S16)+T16) -> 1800 | V16: =U15+V15-W15 -> 2400 | W16: =IF(V16>=$B$24,$B$24,0) -> 2000 | X16: =$B$23+IF(Y16>=$B$25,-$B$23,IF(Y16>=W16*2,-$B$23*0.5,IF(W16>=Y16*2,$B$23*0.5,0))) -> 800 | Y16: =MAX(0,Y15+X15-Z15) -> 2000 | Z16: =IF(AND(Y16>=$B$24,OFFSET(W16,-$B$18,0)>=$B$24),$B$24,0) -> 2000 | AA16: 14
A17: Delivery time to Regional Warehouse | B17: 4 | C17: Week | E17: 15 | F17: =OFFSET(N17,-$B$5,0) -> 0 | G17: =MAX(0,G16+(F16-H16)*$B$2) -> 700 | H17: =MAX(0,IF(G17<$B$6,G17,IF(AND(G17>=$B$6+200,MOD(E17,4)=0),200+$B$6,$B$6))) -> 300 | I17: =MAX(0,($B$8-G17)+H17) -> 900 | J17: =MAX(0,I16-K16+J16) -> 3700 | K17: =IF(J17>=$B$14,$B$14,0) -> 1000 | L17: =OFFSET(T17,-$B$11,0) -> 0 | M17: =MAX(0,M16+(L16-N16)*$B$2) -> 700 | N17: =IF(AND(M17>=$B$14,OFFSET(K17,-$B$7,0)>=$B$14),$B$14,0) -> 0 | O17: =MAX(0,$B$13-M17+N17) -> 800 | P17: =O16-Q16+P16 -> 1200 | Q17: =IF(P17>=$B$20,$B$20,0) -> 0 | R17: =OFFSET(Z17,-$B$17,0) -> 2000 | S17: =MAX(0,S16+(R16-T16)*$B$2) -> 300 | T17: =IF(AND(S17>=$B$20,OFFSET(Q17,-$B$12,0)>=$B$20),$B$20,0) -> 0 | U17: =MAX(0,($B$19-S17)+T17) -> 1800 | V17: =U16+V16-W16 -> 2200 | W17: =IF(V17>=$B$24,$B$24,0) -> 2000 | X17: =$B$23+IF(Y17>=$B$25,-$B$23,IF(Y17>=W17*2,-$B$23*0.5,IF(W17>=Y17*2,$B$23*0.5,0))) -> 1200 | Y17: =MAX(0,Y16+X16-Z16) -> 800 | Z17: =IF(AND(Y17>=$B$24,OFFSET(W17,-$B$18,0)>=$B$24),$B$24,0) -> 0 | AA17: 15
A18: Time to fill oder for to Regional Warehouse | B18: 3 | C18: Week | E18: 16 | F18: =OFFSET(N18,-$B$5,0) -> 0 | G18: =MAX(0,G17+(F17-H17)*$B$2) -> 400 | H18: =MAX(0,IF(G18<$B$6,G18,IF(AND(G18>=$B$6+200,MOD(E18,4)=0),200+$B$6,$B$6))) -> 300 | I18: =MAX(0,($B$8-G18)+H18) -> 1200 | J18: =MAX(0,I17-K17+J17) -> 3600 | K18: =IF(J18>=$B$14,$B$14,0) -> 1000 | L18: =OFFSET(T18,-$B$11,0) -> 0 | M18: =MAX(0,M17+(L17-N17)*$B$2) -> 700 | N18: =IF(AND(M18>=$B$14,OFFSET(K18,-$B$7,0)>=$B$14),$B$14,0) -> 0 | O18: =MAX(0,$B$13-M18+N18) -> 800 | P18: =O17-Q17+P17 -> 2000 | Q18: =IF(P18>=$B$20,$B$20,0) -> 1500 | R18: =OFFSET(Z18,-$B$17,0) -> 2000 | S18: =MAX(0,S17+(R17-T17)*$B$2) -> 2300 | T18: =IF(AND(S18>=$B$20,OFFSET(Q18,-$B$12,0)>=$B$20),$B$20,0) -> 1500 | U18: =MAX(0,($B$19-S18)+T18) -> 1300 | V18: =U17+V17-W17 -> 2000 | W18: =IF(V18>=$B$24,$B$24,0) -> 2000 | X18: =$B$23+IF(Y18>=$B$25,-$B$23,IF(Y18>=W18*2,-$B$23*0.5,IF(W18>=Y18*2,$B$23*0.5,0))) -> 800 | Y18: =MAX(0,Y17+X17-Z17) -> 2000 | Z18: =IF(AND(Y18>=$B$24,OFFSET(W18,-$B$18,0)>=$B$24),$B$24,0) -> 2000 | AA18: 16
A19: Desired supply Regional Warehouse | B19: 2100 | C19: Unit | E19: 17 | F19: =OFFSET(N19,-$B$5,0) -> 0 | G19: =MAX(0,G18+(F18-H18)*$B$2) -> 100 | H19: =MAX(0,IF(G19<$B$6,G19,IF(AND(G19>=$B$6+200,MOD(E19,4)=0),200+$B$6,$B$6))) -> 100 | I19: =MAX(0,($B$8-G19)+H19) -> 1300 | J19: =MAX(0,I18-K18+J18) -> 3800 | K19: =IF(J19>=$B$14,$B$14,0) -> 1000 | L19: =OFFSET(T19,-$B$11,0) -> 0 | M19: =MAX(0,M18+(L18-N18)*$B$2) -> 700 | N19: =IF(AND(M19>=$B$14,OFFSET(K19,-$B$7,0)>=$B$14),$B$14,0) -> 0 | O19: =MAX(0,$B$13-M19+N19) -> 800 | P19: =O18-Q18+P18 -> 1300 | Q19: =IF(P19>=$B$20,$B$20,0) -> 0 | R19: =OFFSET(Z19,-$B$17,0) -> 2000 | S19: =MAX(0,S18+(R18-T18)*$B$2) -> 2800 | T19: =IF(AND(S19>=$B$20,OFFSET(Q19,-$B$12,0)>=$B$20),$B$20,0) -> 0 | U19: =MAX(0,($B$19-S19)+T19) -> 0 | V19: =U18+V18-W18 -> 1300 | W19: =IF(V19>=$B$24,$B$24,0) -> 0 | X19: =$B$23+IF(Y19>=$B$25,-$B$23,IF(Y19>=W19*2,-$B$23*0.5,IF(W19>=Y19*2,$B$23*0.5,0))) -> 400 | Y19: =MAX(0,Y18+X18-Z18) -> 800 | Z19: =IF(AND(Y19>=$B$24,OFFSET(W19,-$B$18,0)>=$B$24),$B$24,0) -> 0 | AA19: 17
A20: Min order size of Regional Warehouse | B20: 1500 | C20: Unit | E20: 18 | F20: =OFFSET(N20,-$B$5,0) -> 0 | G20: =MAX(0,G19+(F19-H19)*$B$2) -> 0 | H20: =MAX(0,IF(G20<$B$6,G20,IF(AND(G20>=$B$6+200,MOD(E20,4)=0),200+$B$6,$B$6))) -> 0 | I20: =MAX(0,($B$8-G20)+H20) -> 1300 | J20: =MAX(0,I19-K19+J19) -> 4100 | K20: =IF(J20>=$B$14,$B$14,0) -> 1000 | L20: =OFFSET(T20,-$B$11,0) -> 0 | M20: =MAX(0,M19+(L19-N19)*$B$2) -> 700 | N20: =IF(AND(M20>=$B$14,OFFSET(K20,-$B$7,0)>=$B$14),$B$14,0) -> 0 | O20: =MAX(0,$B$13-M20+N20) -> 800 | P20: =O19-Q19+P19 -> 2100 | Q20: =IF(P20>=$B$20,$B$20,0) -> 1500 | R20: =OFFSET(Z20,-$B$17,0) -> 2000 | S20: =MAX(0,S19+(R19-T19)*$B$2) -> 4800 | T20: =IF(AND(S20>=$B$20,OFFSET(Q20,-$B$12,0)>=$B$20),$B$20,0) -> 1500 | U20: =MAX(0,($B$19-S20)+T20) -> 0 | V20: =U19+V19-W19 -> 1300 | W20: =IF(V20>=$B$24,$B$24,0) -> 0 | X20: =$B$23+IF(Y20>=$B$25,-$B$23,IF(Y20>=W20*2,-$B$23*0.5,IF(W20>=Y20*2,$B$23*0.5,0))) -> 400 | Y20: =MAX(0,Y19+X19-Z19) -> 1200 | Z20: =IF(AND(Y20>=$B$24,OFFSET(W20,-$B$18,0)>=$B$24),$B$24,0) -> 0 | AA20: 18
E21: 19 | F21: =OFFSET(N21,-$B$5,0) -> 0 | G21: =MAX(0,G20+(F20-H20)*$B$2) -> 0 | H21: =MAX(0,IF(G21<$B$6,G21,IF(AND(G21>=$B$6+200,MOD(E21,4)=0),200+$B$6,$B$6))) -> 0 | I21: =MAX(0,($B$8-G21)+H21) -> 1300 | J21: =MAX(0,I20-K20+J20) -> 4400 | K21: =IF(J21>=$B$14,$B$14,0) -> 1000 | L21: =OFFSET(T21,-$B$11,0) -> 1500 | M21: =MAX(0,M20+(L20-N20)*$B$2) -> 700 | N21: =IF(AND(M21>=$B$14,OFFSET(K21,-$B$7,0)>=$B$14),$B$14,0) -> 0 | O21: =MAX(0,$B$13-M21+N21) -> 800 | P21: =O20-Q20+P20 -> 1400 | Q21: =IF(P21>=$B$20,$B$20,0) -> 0 | R21: =OFFSET(Z21,-$B$17,0) -> 0 | S21: =MAX(0,S20+(R20-T20)*$B$2) -> 5300 | T21: =IF(AND(S21>=$B$20,OFFSET(Q21,-$B$12,0)>=$B$20),$B$20,0) -> 0 | U21: =MAX(0,($B$19-S21)+T21) -> 0 | V21: =U20+V20-W20 -> 1300 | W21: =IF(V21>=$B$24,$B$24,0) -> 0 | X21: =$B$23+IF(Y21>=$B$25,-$B$23,IF(Y21>=W21*2,-$B$23*0.5,IF(W21>=Y21*2,$B$23*0.5,0))) -> 400 | Y21: =MAX(0,Y20+X20-Z20) -> 1600 | Z21: =IF(AND(Y21>=$B$24,OFFSET(W21,-$B$18,0)>=$B$24),$B$24,0) -> 0 | AA21: 19
A22: Initial supply Factory | B22: 2400 | C22: Unit | E22: 20 | F22: =OFFSET(N22,-$B$5,0) -> 0 | G22: =MAX(0,G21+(F21-H21)*$B$2) -> 0 | H22: =MAX(0,IF(G22<$B$6,G22,IF(AND(G22>=$B$6+200,MOD(E22,4)=0),200+$B$6,$B$6))) -> 0 | I22: =MAX(0,($B$8-G22)+H22) -> 1300 | J22: =MAX(0,I21-K21+J21) -> 4700 | K22: =IF(J22>=$B$14,$B$14,0) -> 1000 | L22: =OFFSET(T22,-$B$11,0) -> 0 | M22: =MAX(0,M21+(L21-N21)*$B$2) -> 2200 | N22: =IF(AND(M22>=$B$14,OFFSET(K22,-$B$7,0)>=$B$14),$B$14,0) -> 1000 | O22: =MAX(0,$B$13-M22+N22) -> 300 | P22: =O21-Q21+P21 -> 2200 | Q22: =IF(P22>=$B$20,$B$20,0) -> 1500 | R22: =OFFSET(Z22,-$B$17,0) -> 2000 | S22: =MAX(0,S21+(R21-T21)*$B$2) -> 5300 | T22: =IF(AND(S22>=$B$20,OFFSET(Q22,-$B$12,0)>=$B$20),$B$20,0) -> 1500 | U22: =MAX(0,($B$19-S22)+T22) -> 0 | V22: =U21+V21-W21 -> 1300 | W22: =IF(V22>=$B$24,$B$24,0) -> 0 | X22: =$B$23+IF(Y22>=$B$25,-$B$23,IF(Y22>=W22*2,-$B$23*0.5,IF(W22>=Y22*2,$B$23*0.5,0))) -> 400 | Y22: =MAX(0,Y21+X21-Z21) -> 2000 | Z22: =IF(AND(Y22>=$B$24,OFFSET(W22,-$B$18,0)>=$B$24),$B$24,0) -> 0 | AA22: 20
A23: Average production Factory | B23: 800 | C23: Unit/ Week | E23: 21 | F23: =OFFSET(N23,-$B$5,0) -> 0 | G23: =MAX(0,G22+(F22-H22)*$B$2) -> 0 | H23: =MAX(0,IF(G23<$B$6,G23,IF(AND(G23>=$B$6+200,MOD(E23,4)=0),200+$B$6,$B$6))) -> 0 | I23: =MAX(0,($B$8-G23)+H23) -> 1300 | J23: =MAX(0,I22-K22+J22) -> 5000 | K23: =IF(J23>=$B$14,$B$14,0) -> 1000 | L23: =OFFSET(T23,-$B$11,0) -> 1500 | M23: =MAX(0,M22+(L22-N22)*$B$2) -> 1200 | N23: =IF(AND(M23>=$B$14,OFFSET(K23,-$B$7,0)>=$B$14),$B$14,0) -> 1000 | O23: =MAX(0,$B$13-M23+N23) -> 1300 | P23: =O22-Q22+P22 -> 1000 | Q23: =IF(P23>=$B$20,$B$20,0) -> 0 | R23: =OFFSET(Z23,-$B$17,0) -> 0 | S23: =MAX(0,S22+(R22-T22)*$B$2) -> 5800 | T23: =IF(AND(S23>=$B$20,OFFSET(Q23,-$B$12,0)>=$B$20),$B$20,0) -> 0 | U23: =MAX(0,($B$19-S23)+T23) -> 0 | V23: =U22+V22-W22 -> 1300 | W23: =IF(V23>=$B$24,$B$24,0) -> 0 | X23: =$B$23+IF(Y23>=$B$25,-$B$23,IF(Y23>=W23*2,-$B$23*0.5,IF(W23>=Y23*2,$B$23*0.5,0))) -> 400 | Y23: =MAX(0,Y22+X22-Z22) -> 2400 | Z23: =IF(AND(Y23>=$B$24,OFFSET(W23,-$B$18,0)>=$B$24),$B$24,0) -> 0 | AA23: 21
A24: Min order size of Factory | B24: 2000 | C24: Unit | E24: 22 | F24: =OFFSET(N24,-$B$5,0) -> 1000 | G24: =MAX(0,G23+(F23-H23)*$B$2) -> 0 | H24: =MAX(0,IF(G24<$B$6,G24,IF(AND(G24>=$B$6+200,MOD(E24,4)=0),200+$B$6,$B$6))) -> 0 | I24: =MAX(0,($B$8-G24)+H24) -> 1300 | J24: =MAX(0,I23-K23+J23) -> 5300 | K24: =IF(J24>=$B$14,$B$14,0) -> 1000 | L24: =OFFSET(T24,-$B$11,0) -> 0 | M24: =MAX(0,M23+(L23-N23)*$B$2) -> 1700 | N24: =IF(AND(M24>=$B$14,OFFSET(K24,-$B$7,0)>=$B$14),$B$14,0) -> 1000 | O24: =MAX(0,$B$13-M24+N24) -> 800 | P24: =O23-Q23+P23 -> 2300 | Q24: =IF(P24>=$B$20,$B$20,0) -> 1500 | R24: =OFFSET(Z24,-$B$17,0) -> 0 | S24: =MAX(0,S23+(R23-T23)*$B$2) -> 5800 | T24: =IF(AND(S24>=$B$20,OFFSET(Q24,-$B$12,0)>=$B$20),$B$20,0) -> 1500 | U24: =MAX(0,($B$19-S24)+T24) -> 0 | V24: =U23+V23-W23 -> 1300 | W24: =IF(V24>=$B$24,$B$24,0) -> 0 | X24: =$B$23+IF(Y24>=$B$25,-$B$23,IF(Y24>=W24*2,-$B$23*0.5,IF(W24>=Y24*2,$B$23*0.5,0))) -> 400 | Y24: =MAX(0,Y23+X23-Z23) -> 2800 | Z24: =IF(AND(Y24>=$B$24,OFFSET(W24,-$B$18,0)>=$B$24),$B$24,0) -> 0 | AA24: 22
A25: Max supply Factory | B25: 10000 | C25: Unit | E25: 23 | F25: =OFFSET(N25,-$B$5,0) -> 1000 | G25: =MAX(0,G24+(F24-H24)*$B$2) -> 1000 | H25: =MAX(0,IF(G25<$B$6,G25,IF(AND(G25>=$B$6+200,MOD(E25,4)=0),200+$B$6,$B$6))) -> 300 | I25: =MAX(0,($B$8-G25)+H25) -> 600 | J25: =MAX(0,I24-K24+J24) -> 5600 | K25: =IF(J25>=$B$14,$B$14,0) -> 1000 | L25: =OFFSET(T25,-$B$11,0) -> 1500 | M25: =MAX(0,M24+(L24-N24)*$B$2) -> 700 | N25: =IF(AND(M25>=$B$14,OFFSET(K25,-$B$7,0)>=$B$14),$B$14,0) -> 0 | O25: =MAX(0,$B$13-M25+N25) -> 800 | P25: =O24-Q24+P24 -> 1600 | Q25: =IF(P25>=$B$20,$B$20,0) -> 1500 | R25: =OFFSET(Z25,-$B$17,0) -> 0 | S25: =MAX(0,S24+(R24-T24)*$B$2) -> 4300 | T25: =IF(AND(S25>=$B$20,OFFSET(Q25,-$B$12,0)>=$B$20),$B$20,0) -> 0 | U25: =MAX(0,($B$19-S25)+T25) -> 0 | V25: =U24+V24-W24 -> 1300 | W25: =IF(V25>=$B$24,$B$24,0) -> 0 | X25: =$B$23+IF(Y25>=$B$25,-$B$23,IF(Y25>=W25*2,-$B$23*0.5,IF(W25>=Y25*2,$B$23*0.5,0))) -> 400 | Y25: =MAX(0,Y24+X24-Z24) -> 3200 | Z25: =IF(AND(Y25>=$B$24,OFFSET(W25,-$B$18,0)>=$B$24),$B$24,0) -> 0 | AA25: 23
E26: 24 | F26: =OFFSET(N26,-$B$5,0) -> 1000 | G26: =MAX(0,G25+(F25-H25)*$B$2) -> 1700 | H26: =MAX(0,IF(G26<$B$6,G26,IF(AND(G26>=$B$6+200,MOD(E26,4)=0),200+$B$6,$B$6))) -> 500 | I26: =MAX(0,($B$8-G26)+H26) -> 100 | J26: =MAX(0,I25-K25+J25) -> 5200 | K26: =IF(J26>=$B$14,$B$14,0) -> 1000 | L26: =OFFSET(T26,-$B$11,0) -> 0 | M26: =MAX(0,M25+(L25-N25)*$B$2) -> 2200 | N26: =IF(AND(M26>=$B$14,OFFSET(K26,-$B$7,0)>=$B$14),$B$14,0) -> 1000 | O26: =MAX(0,$B$13-M26+N26) -> 300 | P26: =O25-Q25+P25 -> 900 | Q26: =IF(P26>=$B$20,$B$20,0) -> 0 | R26: =OFFSET(Z26,-$B$17,0) -> 0 | S26: =MAX(0,S25+(R25-T25)*$B$2) -> 4300 | T26: =IF(AND(S26>=$B$20,OFFSET(Q26,-$B$12,0)>=$B$20),$B$20,0) -> 1500 | U26: =MAX(0,($B$19-S26)+T26) -> 0 | V26: =U25+V25-W25 -> 1300 | W26: =IF(V26>=$B$24,$B$24,0) -> 0 | X26: =$B$23+IF(Y26>=$B$25,-$B$23,IF(Y26>=W26*2,-$B$23*0.5,IF(W26>=Y26*2,$B$23*0.5,0))) -> 400 | Y26: =MAX(0,Y25+X25-Z25) -> 3600 | Z26: =IF(AND(Y26>=$B$24,OFFSET(W26,-$B$18,0)>=$B$24),$B$24,0) -> 0 | AA26: 24
E27: 25 | F27: =OFFSET(N27,-$B$5,0) -> 0 | G27: =MAX(0,G26+(F26-H26)*$B$2) -> 2200 | H27: =MAX(0,IF(G27<$B$6,G27,IF(AND(G27>=$B$6+200,MOD(E27,4)=0),200+$B$6,$B$6))) -> 300 | I27: =MAX(0,($B$8-G27)+H27) -> 0 | J27: =MAX(0,I26-K26+J26) -> 4300 | K27: =IF(J27>=$B$14,$B$14,0) -> 1000 | L27: =OFFSET(T27,-$B$11,0) -> 1500 | M27: =MAX(0,M26+(L26-N26)*$B$2) -> 1200 | N27: =IF(AND(M27>=$B$14,OFFSET(K27,-$B$7,0)>=$B$14),$B$14,0) -> 1000 | O27: =MAX(0,$B$13-M27+N27) -> 1300 | P27: =O26-Q26+P26 -> 1200 | Q27: =IF(P27>=$B$20,$B$20,0) -> 0 | R27: =OFFSET(Z27,-$B$17,0) -> 0 | S27: =MAX(0,S26+(R26-T26)*$B$2) -> 2800 | T27: =IF(AND(S27>=$B$20,OFFSET(Q27,-$B$12,0)>=$B$20),$B$20,0) -> 1500 | U27: =MAX(0,($B$19-S27)+T27) -> 800 | V27: =U26+V26-W26 -> 1300 | W27: =IF(V27>=$B$24,$B$24,0) -> 0 | X27: =$B$23+IF(Y27>=$B$25,-$B$23,IF(Y27>=W27*2,-$B$23*0.5,IF(W27>=Y27*2,$B$23*0.5,0))) -> 400 | Y27: =MAX(0,Y26+X26-Z26) -> 4000 | Z27: =IF(AND(Y27>=$B$24,OFFSET(W27,-$B$18,0)>=$B$24),$B$24,0) -> 0 | AA27: 25
E28: 26 | F28: =OFFSET(N28,-$B$5,0) -> 1000 | G28: =MAX(0,G27+(F27-H27)*$B$2) -> 1900 | H28: =MAX(0,IF(G28<$B$6,G28,IF(AND(G28>=$B$6+200,MOD(E28,4)=0),200+$B$6,$B$6))) -> 300 | I28: =MAX(0,($B$8-G28)+H28) -> 0 | J28: =MAX(0,I27-K27+J27) -> 3300 | K28: =IF(J28>=$B$14,$B$14,0) -> 1000 | L28: =OFFSET(T28,-$B$11,0) -> 0 | M28: =MAX(0,M27+(L27-N27)*$B$2) -> 1700 | N28: =IF(AND(M28>=$B$14,OFFSET(K28,-$B$7,0)>=$B$14),$B$14,0) -> 1000 | O28: =MAX(0,$B$13-M28+N28) -> 800 | P28: =O27-Q27+P27 -> 2500 | Q28: =IF(P28>=$B$20,$B$20,0) -> 1500 | R28: =OFFSET(Z28,-$B$17,0) -> 0 | S28: =MAX(0,S27+(R27-T27)*$B$2) -> 1300 | T28: =IF(AND(S28>=$B$20,OFFSET(Q28,-$B$12,0)>=$B$20),$B$20,0) -> 0 | U28: =MAX(0,($B$19-S28)+T28) -> 800 | V28: =U27+V27-W27 -> 2100 | W28: =IF(V28>=$B$24,$B$24,0) -> 2000 | X28: =$B$23+IF(Y28>=$B$25,-$B$23,IF(Y28>=W28*2,-$B$23*0.5,IF(W28>=Y28*2,$B$23*0.5,0))) -> 400 | Y28: =MAX(0,Y27+X27-Z27) -> 4400 | Z28: =IF(AND(Y28>=$B$24,OFFSET(W28,-$B$18,0)>=$B$24),$B$24,0) -> 0 | AA28: 26
